Workbook

Sheet Client Tracker
A1: 🐛 DRUDGE PEST CONTROL — Client & Visit Tracker
A2: SITE INFORMATION | M2: STATUS | N2: VISITS | O2: VISIT 1 | AB2: VISIT 2 | AO2: VISIT 3 | BB2: VISIT 4 | BO2: VISIT 5 | CB2: VISIT 6 | CO2: VISIT 7 | DB2: VISIT 8 | DO2: VISIT 9 | EB2: VISIT 10 | EO2: VISIT 11 | FB2: VISIT 12 | FO2: TOTALS SUMMARY | FW2: EMERGENCY | FX2: GRAND TOTAL
A3: Site ID | B3: Site Administration | C3: Site Name | D3: Site tibe | E3: Location | F3: Governorate | G3: Visit Day (Weekday) | I3: Visit Hour | J3: Visit Duration | K3: Flybait | L3: Scheduled Visits | M3: Visit Status (Auto) | N3: Total Visits Done | O3: Visit Date | P3: Done ✔ | Q3: Spare Parts Changed | R3: Lamps Used | S3: Cables Used | T3: Transformers Used | U3: Light Sheets Used | V3: Fipronil (ml) | W3: Imidacloprid (gm) | X3: Baits (#) | Y3: Glo Pieces (#) | Z3: Branch Issue | AA3: Notes | AB3: Visit Date | AC3: Done ✔ | AD3: Spare Parts Changed | AE3: Lamps Used | AF3: Cables Used | AG3: Transformers Used | AH3: Light Sheets Used | AI3: Fipronil (ml) | AJ3: Imidacloprid (gm) | AK3: Baits (#) | AL3: Glo Pieces (#) | AM3: Branch Issue | AN3: Notes | AO3: Visit Date | AP3: Done ✔ | AQ3: Spare Parts Changed | AR3: Lamps Used | AS3: Cables Used | AT3: Transformers Used | AU3: Light Sheets Used | AV3: Fipronil (ml) | AW3: Imidacloprid (gm) | AX3: Baits (#) | AY3: Glo Pieces (#) | AZ3: Branch Issue | BA3: Notes | BB3: Visit Date | BC3: Done ✔ | BD3: Spare Parts Changed | BE3: Lamps Used | BF3: Cables Used | BG3: Transformers Used | BH3: Light Sheets Used | BI3: Fipronil (ml) | BJ3: Imidacloprid (gm) | BK3: Baits (#) | BL3: Glo Pieces (#) | BM3: Branch Issue | BN3: Notes | BO3: Visit Date | BP3: Done ✔ | BQ3: Spare Parts Changed | BR3: Lamps Used | BS3: Cables Used | BT3: Transformers Used | BU3: Light Sheets Used | BV3: Fipronil (ml) | BW3: Imidacloprid (gm) | BX3: Baits (#) | BY3: Glo Pieces (#) | BZ3: Branch Issue | CA3: Notes | CB3: Visit Date | CC3: Done ✔ | CD3: Spare Parts Changed | CE3: Lamps Used | CF3: Cables Used | CG3: Transformers Used | CH3: Light Sheets Used | CI3: Fipronil (ml) | CJ3: Imidacloprid (gm) | CK3: Baits (#) | CL3: Glo Pieces (#) | CM3: Branch Issue | CN3: Notes | CO3: Visit Date | CP3: Done ✔ | CQ3: Spare Parts Changed | CR3: Lamps Used | CS3: Cables Used | CT3: Transformers Used | CU3: Light Sheets Used | CV3: Fipronil (ml) | CW3: Imidacloprid (gm) | CX3: Baits (#) | CY3: Glo Pieces (#) | CZ3: Branch Issue | DA3: Notes | DB3: Visit Date | DC3: Done ✔ | DD3: Spare Parts Changed | DE3: Lamps Used | DF3: Cables Used | DG3: Transformers Used | DH3: Light Sheets Used | DI3: Fipronil (ml) | DJ3: Imidacloprid (gm) | DK3: Baits (#) | DL3: Glo Pieces (#) | DM3: Branch Issue | DN3: Notes | DO3: Visit Date | DP3: Done ✔ | DQ3: Spare Parts Changed | DR3: Lamps Used | DS3: Cables Used | DT3: Transformers Used | DU3: Light Sheets Used | DV3: Fipronil (ml) | DW3: Imidacloprid (gm) | DX3: Baits (#) | DY3: Glo Pieces (#) | DZ3: Branch Issue | EA3: Notes | EB3: Visit Date | EC3: Done ✔ | ED3: Spare Parts Changed | EE3: Lamps Used | EF3: Cables Used | EG3: Transformers Used | EH3: Light Sheets Used | EI3: Fipronil (ml) | EJ3: Imidacloprid (gm) | EK3: Baits (#) | EL3: Glo Pieces (#) | EM3: Branch Issue | EN3: Notes | EO3: Visit Date | EP3: Done ✔ | EQ3: Spare Parts Changed | ER3: Lamps Used | ES3: Cables Used | ET3: Transformers Used | EU3: Light Sheets Used | EV3: Fipronil (ml) | EW3: Imidacloprid (gm) | EX3: Baits (#) | EY3: Glo Pieces (#) | EZ3: Branch Issue | FA3: Notes | FB3: Visit Date | FC3: Done ✔ | FD3: Spare Parts Changed | FE3: Lamps Used | FF3: Cables Used | FG3: Transformers Used | FH3: Light Sheets Used | FI3: Fipronil (ml) | FJ3: Imidacloprid (gm) | FK3: Baits (#) | FL3: Glo Pieces (#) | FM3: Branch Issue | FN3: Notes | FO3: Total Lamps Used | FP3: Total Cables Used | FQ3: Total Transformers | FR3: Total Light Sheets | FS3: Total Fipronil (ml) | FT3: Total Imidacloprid (gm) | FU3: Total Baits (#) | FV3: Total Glo Pieces (#) | FW3: Emergency Visits (#) | FX3: Grand Total All Visits
A4: =IF(C4<>"","DRG-"&TEXT(1,"000"),"") -> DRG-001 | B4: Exception | C4: Exception | D4: Brunche | E4: فيصل | F4: Giza | G4: Sunday | I4: 0.95833333 | J4: 45min | K4: 2 | L4: 4 | M4: =IF(N4>=4,"✔ Completed","✘ Pending") -> ✔ Completed | N4: =(P4="✔")+(AC4="✔")+(AP4="✔")+(BC4="✔")+(BP4="✔")+(CC4="✔")+(CP4="✔")+(DC4="✔")+(DP4="✔")+(EC4="✔")+(EP4="✔")+(FC4="✔") -> 4 | O4: 46028 | P4: ✔ | R4: 2 | S4: 0 | T4: 1 | U4: 1 | V4: 50mil | W4: 10g | X4: 10 | Y4: 5 | AC4: ✔ | AP4: ✔ | BC4: ✔ | FO4: =IFERROR(R4*1,0)+IFERROR(AE4*1,0)+IFERROR(AR4*1,0)+IFERROR(BE4*1,0)+IFERROR(BR4*1,0)+IFERROR(CE4*1,0)+IFERROR(CR4*1,0)+IFERROR(DE4*1,0)+IFERROR(DR4*1,0)+IFERROR(EE4*1,0)+IFERROR(ER4*1,0)+IFERROR(FE4*1,0) -> 2 | FP4: =IFERROR(S4*1,0)+IFERROR(AF4*1,0)+IFERROR(AS4*1,0)+IFERROR(BF4*1,0)+IFERROR(BS4*1,0)+IFERROR(CF4*1,0)+IFERROR(CS4*1,0)+IFERROR(DF4*1,0)+IFERROR(DS4*1,0)+IFERROR(EF4*1,0)+IFERROR(ES4*1,0)+IFERROR(FF4*1,0) -> 0 | FQ4: =IFERROR(T4*1,0)+IFERROR(AG4*1,0)+IFERROR(AT4*1,0)+IFERROR(BG4*1,0)+IFERROR(BT4*1,0)+IFERROR(CG4*1,0)+IFERROR(CT4*1,0)+IFERROR(DG4*1,0)+IFERROR(DT4*1,0)+IFERROR(EG4*1,0)+IFERROR(ET4*1,0)+IFERROR(FG4*1,0) -> 1 | FR4: =IFERROR(U4*1,0)+IFERROR(AH4*1,0)+IFERROR(AU4*1,0)+IFERROR(BH4*1,0)+IFERROR(BU4*1,0)+IFERROR(CH4*1,0)+IFERROR(CU4*1,0)+IFERROR(DH4*1,0)+IFERROR(DU4*1,0)+IFERROR(EH4*1,0)+IFERROR(EU4*1,0)+IFERROR(FH4*1,0) -> 1 | FS4: =IFERROR(V4*1,0)+IFERROR(AI4*1,0)+IFERROR(AV4*1,0)+IFERROR(BI4*1,0)+IFERROR(BV4*1,0)+IFERROR(CI4*1,0)+IFERROR(CV4*1,0)+IFERROR(DI4*1,0)+IFERROR(DV4*1,0)+IFERROR(EI4*1,0)+IFERROR(EV4*1,0)+IFERROR(FI4*1,0) -> 0 | FT4: =IFERROR(W4*1,0)+IFERROR(AJ4*1,0)+IFERROR(AW4*1,0)+IFERROR(BJ4*1,0)+IFERROR(BW4*1,0)+IFERROR(CJ4*1,0)+IFERROR(CW4*1,0)+IFERROR(DJ4*1,0)+IFERROR(DW4*1,0)+IFERROR(EJ4*1,0)+IFERROR(EW4*1,0)+IFERROR(FJ4*1,0) -> 0 | FU4: =IFERROR(X4*1,0)+IFERROR(AK4*1,0)+IFERROR(AX4*1,0)+IFERROR(BK4*1,0)+IFERROR(BX4*1,0)+IFERROR(CK4*1,0)+IFERROR(CX4*1,0)+IFERROR(DK4*1,0)+IFERROR(DX4*1,0)+IFERROR(EK4*1,0)+IFERROR(EX4*1,0)+IFERROR(FK4*1,0) -> 10 | FV4: =IFERROR(Y4*1,0)+IFERROR(AL4*1,0)+IFERROR(AY4*1,0)+IFERROR(BL4*1,0)+IFERROR(BY4*1,0)+IFERROR(CL4*1,0)+IFERROR(CY4*1,0)+IFERROR(DL4*1,0)+IFERROR(DY4*1,0)+IFERROR(EL4*1,0)+IFERROR(EY4*1,0)+IFERROR(FL4*1,0) -> 5 | FX4: =N4+IFERROR(FW4*1,0) -> 4
A5: =IF(C5<>"","DRG-"&TEXT(2,"000"),"") -> DRG-002 | B5: Exception | C5: Exception | D5: Brunche | E5: سهل حمزه | F5: Giza | I5: 0.95833333 | L5: 4 | M5: =IF(N5>=4,"✔ Completed","✘ Pending") -> ✘ Pending | N5: =(P5="✔")+(AC5="✔")+(AP5="✔")+(BC5="✔")+(BP5="✔")+(CC5="✔")+(CP5="✔")+(DC5="✔")+(DP5="✔")+(EC5="✔")+(EP5="✔")+(FC5="✔") -> 0 | FO5: =IFERROR(R5*1,0)+IFERROR(AE5*1,0)+IFERROR(AR5*1,0)+IFERROR(BE5*1,0)+IFERROR(BR5*1,0)+IFERROR(CE5*1,0)+IFERROR(CR5*1,0)+IFERROR(DE5*1,0)+IFERROR(DR5*1,0)+IFERROR(EE5*1,0)+IFERROR(ER5*1,0)+IFERROR(FE5*1,0) -> 0 | FP5: =IFERROR(S5*1,0)+IFERROR(AF5*1,0)+IFERROR(AS5*1,0)+IFERROR(BF5*1,0)+IFERROR(BS5*1,0)+IFERROR(CF5*1,0)+IFERROR(CS5*1,0)+IFERROR(DF5*1,0)+IFERROR(DS5*1,0)+IFERROR(EF5*1,0)+IFERROR(ES5*1,0)+IFERROR(FF5*1,0) -> 0 | FQ5: =IFERROR(T5*1,0)+IFERROR(AG5*1,0)+IFERROR(AT5*1,0)+IFERROR(BG5*1,0)+IFERROR(BT5*1,0)+IFERROR(CG5*1,0)+IFERROR(CT5*1,0)+IFERROR(DG5*1,0)+IFERROR(DT5*1,0)+IFERROR(EG5*1,0)+IFERROR(ET5*1,0)+IFERROR(FG5*1,0) -> 0 | FR5: =IFERROR(U5*1,0)+IFERROR(AH5*1,0)+IFERROR(AU5*1,0)+IFERROR(BH5*1,0)+IFERROR(BU5*1,0)+IFERROR(CH5*1,0)+IFERROR(CU5*1,0)+IFERROR(DH5*1,0)+IFERROR(DU5*1,0)+IFERROR(EH5*1,0)+IFERROR(EU5*1,0)+IFERROR(FH5*1,0) -> 0 | FS5: =IFERROR(V5*1,0)+IFERROR(AI5*1,0)+IFERROR(AV5*1,0)+IFERROR(BI5*1,0)+IFERROR(BV5*1,0)+IFERROR(CI5*1,0)+IFERROR(CV5*1,0)+IFERROR(DI5*1,0)+IFERROR(DV5*1,0)+IFERROR(EI5*1,0)+IFERROR(EV5*1,0)+IFERROR(FI5*1,0) -> 0 | FT5: =IFERROR(W5*1,0)+IFERROR(AJ5*1,0)+IFERROR(AW5*1,0)+IFERROR(BJ5*1,0)+IFERROR(BW5*1,0)+IFERROR(CJ5*1,0)+IFERROR(CW5*1,0)+IFERROR(DJ5*1,0)+IFERROR(DW5*1,0)+IFERROR(EJ5*1,0)+IFERROR(EW5*1,0)+IFERROR(FJ5*1,0) -> 0 | FU5: =IFERROR(X5*1,0)+IFERROR(AK5*1,0)+IFERROR(AX5*1,0)+IFERROR(BK5*1,0)+IFERROR(BX5*1,0)+IFERROR(CK5*1,0)+IFERROR(CX5*1,0)+IFERROR(DK5*1,0)+IFERROR(DX5*1,0)+IFERROR(EK5*1,0)+IFERROR(EX5*1,0)+IFERROR(FK5*1,0) -> 0 | FV5: =IFERROR(Y5*1,0)+IFERROR(AL5*1,0)+IFERROR(AY5*1,0)+IFERROR(BL5*1,0)+IFERROR(BY5*1,0)+IFERROR(CL5*1,0)+IFERROR(CY5*1,0)+IFERROR(DL5*1,0)+IFERROR(DY5*1,0)+IFERROR(EL5*1,0)+IFERROR(EY5*1,0)+IFERROR(FL5*1,0) -> 0 | FX5: =N5+IFERROR(FW5*1,0) -> 0
A6: =IF(C6<>"","DRG-"&TEXT(3,"000"),"") -> DRG-003 | B6: Exception | C6: Exception | D6: Brunche | E6: ترسا | F6: Giza | I6: 0.95833333 | L6: 4 | M6: =IF(N6>=4,"✔ Completed","✘ Pending") -> ✘ Pending | N6: =(P6="✔")+(AC6="✔")+(AP6="✔")+(BC6="✔")+(BP6="✔")+(CC6="✔")+(CP6="✔")+(DC6="✔")+(DP6="✔")+(EC6="✔")+(EP6="✔")+(FC6="✔") -> 0 | FO6: =IFERROR(R6*1,0)+IFERROR(AE6*1,0)+IFERROR(AR6*1,0)+IFERROR(BE6*1,0)+IFERROR(BR6*1,0)+IFERROR(CE6*1,0)+IFERROR(CR6*1,0)+IFERROR(DE6*1,0)+IFERROR(DR6*1,0)+IFERROR(EE6*1,0)+IFERROR(ER6*1,0)+IFERROR(FE6*1,0) -> 0 | FP6: =IFERROR(S6*1,0)+IFERROR(AF6*1,0)+IFERROR(AS6*1,0)+IFERROR(BF6*1,0)+IFERROR(BS6*1,0)+IFERROR(CF6*1,0)+IFERROR(CS6*1,0)+IFERROR(DF6*1,0)+IFERROR(DS6*1,0)+IFERROR(EF6*1,0)+IFERROR(ES6*1,0)+IFERROR(FF6*1,0) -> 0 | FQ6: =IFERROR(T6*1,0)+IFERROR(AG6*1,0)+IFERROR(AT6*1,0)+IFERROR(BG6*1,0)+IFERROR(BT6*1,0)+IFERROR(CG6*1,0)+IFERROR(CT6*1,0)+IFERROR(DG6*1,0)+IFERROR(DT6*1,0)+IFERROR(EG6*1,0)+IFERROR(ET6*1,0)+IFERROR(FG6*1,0) -> 0 | FR6: =IFERROR(U6*1,0)+IFERROR(AH6*1,0)+IFERROR(AU6*1,0)+IFERROR(BH6*1,0)+IFERROR(BU6*1,0)+IFERROR(CH6*1,0)+IFERROR(CU6*1,0)+IFERROR(DH6*1,0)+IFERROR(DU6*1,0)+IFERROR(EH6*1,0)+IFERROR(EU6*1,0)+IFERROR(FH6*1,0) -> 0 | FS6: =IFERROR(V6*1,0)+IFERROR(AI6*1,0)+IFERROR(AV6*1,0)+IFERROR(BI6*1,0)+IFERROR(BV6*1,0)+IFERROR(CI6*1,0)+IFERROR(CV6*1,0)+IFERROR(DI6*1,0)+IFERROR(DV6*1,0)+IFERROR(EI6*1,0)+IFERROR(EV6*1,0)+IFERROR(FI6*1,0) -> 0 | FT6: =IFERROR(W6*1,0)+IFERROR(AJ6*1,0)+IFERROR(AW6*1,0)+IFERROR(BJ6*1,0)+IFERROR(BW6*1,0)+IFERROR(CJ6*1,0)+IFERROR(CW6*1,0)+IFERROR(DJ6*1,0)+IFERROR(DW6*1,0)+IFERROR(EJ6*1,0)+IFERROR(EW6*1,0)+IFERROR(FJ6*1,0) -> 0 | FU6: =IFERROR(X6*1,0)+IFERROR(AK6*1,0)+IFERROR(AX6*1,0)+IFERROR(BK6*1,0)+IFERROR(BX6*1,0)+IFERROR(CK6*1,0)+IFERROR(CX6*1,0)+IFERROR(DK6*1,0)+IFERROR(DX6*1,0)+IFERROR(EK6*1,0)+IFERROR(EX6*1,0)+IFERROR(FK6*1,0) -> 0 | FV6: =IFERROR(Y6*1,0)+IFERROR(AL6*1,0)+IFERROR(AY6*1,0)+IFERROR(BL6*1,0)+IFERROR(BY6*1,0)+IFERROR(CL6*1,0)+IFERROR(CY6*1,0)+IFERROR(DL6*1,0)+IFERROR(DY6*1,0)+IFERROR(EL6*1,0)+IFERROR(EY6*1,0)+IFERROR(FL6*1,0) -> 0 | FX6: =N6+IFERROR(FW6*1,0) -> 0
A7: =IF(C7<>"","DRG-"&TEXT(4,"000"),"") -> DRG-004 | B7: Exception | C7: Exception | D7: Brunche | E7: المنصوريه | F7: Giza | I7: 0.95833333 | L7: 4 | M7: =IF(N7>=4,"✔ Completed","✘ Pending") -> ✘ Pending | N7: =(P7="✔")+(AC7="✔")+(AP7="✔")+(BC7="✔")+(BP7="✔")+(CC7="✔")+(CP7="✔")+(DC7="✔")+(DP7="✔")+(EC7="✔")+(EP7="✔")+(FC7="✔") -> 0 | FO7: =IFERROR(R7*1,0)+IFERROR(AE7*1,0)+IFERROR(AR7*1,0)+IFERROR(BE7*1,0)+IFERROR(BR7*1,0)+IFERROR(CE7*1,0)+IFERROR(CR7*1,0)+IFERROR(DE7*1,0)+IFERROR(DR7*1,0)+IFERROR(EE7*1,0)+IFERROR(ER7*1,0)+IFERROR(FE7*1,0) -> 0 | FP7: =IFERROR(S7*1,0)+IFERROR(AF7*1,0)+IFERROR(AS7*1,0)+IFERROR(BF7*1,0)+IFERROR(BS7*1,0)+IFERROR(CF7*1,0)+IFERROR(CS7*1,0)+IFERROR(DF7*1,0)+IFERROR(DS7*1,0)+IFERROR(EF7*1,0)+IFERROR(ES7*1,0)+IFERROR(FF7*1,0) -> 0 | FQ7: =IFERROR(T7*1,0)+IFERROR(AG7*1,0)+IFERROR(AT7*1,0)+IFERROR(BG7*1,0)+IFERROR(BT7*1,0)+IFERROR(CG7*1,0)+IFERROR(CT7*1,0)+IFERROR(DG7*1,0)+IFERROR(DT7*1,0)+IFERROR(EG7*1,0)+IFERROR(ET7*1,0)+IFERROR(FG7*1,0) -> 0 | FR7: =IFERROR(U7*1,0)+IFERROR(AH7*1,0)+IFERROR(AU7*1,0)+IFERROR(BH7*1,0)+IFERROR(BU7*1,0)+IFERROR(CH7*1,0)+IFERROR(CU7*1,0)+IFERROR(DH7*1,0)+IFERROR(DU7*1,0)+IFERROR(EH7*1,0)+IFERROR(EU7*1,0)+IFERROR(FH7*1,0) -> 0 | FS7: =IFERROR(V7*1,0)+IFERROR(AI7*1,0)+IFERROR(AV7*1,0)+IFERROR(BI7*1,0)+IFERROR(BV7*1,0)+IFERROR(CI7*1,0)+IFERROR(CV7*1,0)+IFERROR(DI7*1,0)+IFERROR(DV7*1,0)+IFERROR(EI7*1,0)+IFERROR(EV7*1,0)+IFERROR(FI7*1,0) -> 0 | FT7: =IFERROR(W7*1,0)+IFERROR(AJ7*1,0)+IFERROR(AW7*1,0)+IFERROR(BJ7*1,0)+IFERROR(BW7*1,0)+IFERROR(CJ7*1,0)+IFERROR(CW7*1,0)+IFERROR(DJ7*1,0)+IFERROR(DW7*1,0)+IFERROR(EJ7*1,0)+IFERROR(EW7*1,0)+IFERROR(FJ7*1,0) -> 0 | FU7: =IFERROR(X7*1,0)+IFERROR(AK7*1,0)+IFERROR(AX7*1,0)+IFERROR(BK7*1,0)+IFERROR(BX7*1,0)+IFERROR(CK7*1,0)+IFERROR(CX7*1,0)+IFERROR(DK7*1,0)+IFERROR(DX7*1,0)+IFERROR(EK7*1,0)+IFERROR(EX7*1,0)+IFERROR(FK7*1,0) -> 0 | FV7: =IFERROR(Y7*1,0)+IFERROR(AL7*1,0)+IFERROR(AY7*1,0)+IFERROR(BL7*1,0)+IFERROR(BY7*1,0)+IFERROR(CL7*1,0)+IFERROR(CY7*1,0)+IFERROR(DL7*1,0)+IFERROR(DY7*1,0)+IFERROR(EL7*1,0)+IFERROR(EY7*1,0)+IFERROR(FL7*1,0) -> 0 | FX7: =N7+IFERROR(FW7*1,0) -> 0
A8: =IF(C8<>"","DRG-"&TEXT(5,"000"),"") -> DRG-005 | B8: Exception | C8: Exception | D8: Brunche | E8: حدائق اكتوبر | F8: Giza | I8: 0.95833333 | L8: 4 | M8: =IF(N8>=4,"✔ Completed","✘ Pending") -> ✘ Pending | N8: =(P8="✔")+(AC8="✔")+(AP8="✔")+(BC8="✔")+(BP8="✔")+(CC8="✔")+(CP8="✔")+(DC8="✔")+(DP8="✔")+(EC8="✔")+(EP8="✔")+(FC8="✔") -> 0 | FO8: =IFERROR(R8*1,0)+IFERROR(AE8*1,0)+IFERROR(AR8*1,0)+IFERROR(BE8*1,0)+IFERROR(BR8*1,0)+IFERROR(CE8*1,0)+IFERROR(CR8*1,0)+IFERROR(DE8*1,0)+IFERROR(DR8*1,0)+IFERROR(EE8*1,0)+IFERROR(ER8*1,0)+IFERROR(FE8*1,0) -> 0 | FP8: =IFERROR(S8*1,0)+IFERROR(AF8*1,0)+IFERROR(AS8*1,0)+IFERROR(BF8*1,0)+IFERROR(BS8*1,0)+IFERROR(CF8*1,0)+IFERROR(CS8*1,0)+IFERROR(DF8*1,0)+IFERROR(DS8*1,0)+IFERROR(EF8*1,0)+IFERROR(ES8*1,0)+IFERROR(FF8*1,0) -> 0 | FQ8: =IFERROR(T8*1,0)+IFERROR(AG8*1,0)+IFERROR(AT8*1,0)+IFERROR(BG8*1,0)+IFERROR(BT8*1,0)+IFERROR(CG8*1,0)+IFERROR(CT8*1,0)+IFERROR(DG8*1,0)+IFERROR(DT8*1,0)+IFERROR(EG8*1,0)+IFERROR(ET8*1,0)+IFERROR(FG8*1,0) -> 0 | FR8: =IFERROR(U8*1,0)+IFERROR(AH8*1,0)+IFERROR(AU8*1,0)+IFERROR(BH8*1,0)+IFERROR(BU8*1,0)+IFERROR(CH8*1,0)+IFERROR(CU8*1,0)+IFERROR(DH8*1,0)+IFERROR(DU8*1,0)+IFERROR(EH8*1,0)+IFERROR(EU8*1,0)+IFERROR(FH8*1,0) -> 0 | FS8: =IFERROR(V8*1,0)+IFERROR(AI8*1,0)+IFERROR(AV8*1,0)+IFERROR(BI8*1,0)+IFERROR(BV8*1,0)+IFERROR(CI8*1,0)+IFERROR(CV8*1,0)+IFERROR(DI8*1,0)+IFERROR(DV8*1,0)+IFERROR(EI8*1,0)+IFERROR(EV8*1,0)+IFERROR(FI8*1,0) -> 0 | FT8: =IFERROR(W8*1,0)+IFERROR(AJ8*1,0)+IFERROR(AW8*1,0)+IFERROR(BJ8*1,0)+IFERROR(BW8*1,0)+IFERROR(CJ8*1,0)+IFERROR(CW8*1,0)+IFERROR(DJ8*1,0)+IFERROR(DW8*1,0)+IFERROR(EJ8*1,0)+IFERROR(EW8*1,0)+IFERROR(FJ8*1,0) -> 0 | FU8: =IFERROR(X8*1,0)+IFERROR(AK8*1,0)+IFERROR(AX8*1,0)+IFERROR(BK8*1,0)+IFERROR(BX8*1,0)+IFERROR(CK8*1,0)+IFERROR(CX8*1,0)+IFERROR(DK8*1,0)+IFERROR(DX8*1,0)+IFERROR(EK8*1,0)+IFERROR(EX8*1,0)+IFERROR(FK8*1,0) -> 0 | FV8: =IFERROR(Y8*1,0)+IFERROR(AL8*1,0)+IFERROR(AY8*1,0)+IFERROR(BL8*1,0)+IFERROR(BY8*1,0)+IFERROR(CL8*1,0)+IFERROR(CY8*1,0)+IFERROR(DL8*1,0)+IFERROR(DY8*1,0)+IFERROR(EL8*1,0)+IFERROR(EY8*1,0)+IFERROR(FL8*1,0) -> 0 | FX8: =N8+IFERROR(FW8*1,0) -> 0
A9: =IF(C9<>"","DRG-"&TEXT(6,"000"),"") -> DRG-006 | B9: Exception | C9: Exception | D9: Brunche | E9: هضبه أ | F9: Cairo | I9: 0.95833333 | L9: 4 | M9: =IF(N9>=4,"✔ Completed","✘ Pending") -> ✘ Pending | N9: =(P9="✔")+(AC9="✔")+(AP9="✔")+(BC9="✔")+(BP9="✔")+(CC9="✔")+(CP9="✔")+(DC9="✔")+(DP9="✔")+(EC9="✔")+(EP9="✔")+(FC9="✔") -> 0 | FO9: =IFERROR(R9*1,0)+IFERROR(AE9*1,0)+IFERROR(AR9*1,0)+IFERROR(BE9*1,0)+IFERROR(BR9*1,0)+IFERROR(CE9*1,0)+IFERROR(CR9*1,0)+IFERROR(DE9*1,0)+IFERROR(DR9*1,0)+IFERROR(EE9*1,0)+IFERROR(ER9*1,0)+IFERROR(FE9*1,0) -> 0 | FP9: =IFERROR(S9*1,0)+IFERROR(AF9*1,0)+IFERROR(AS9*1,0)+IFERROR(BF9*1,0)+IFERROR(BS9*1,0)+IFERROR(CF9*1,0)+IFERROR(CS9*1,0)+IFERROR(DF9*1,0)+IFERROR(DS9*1,0)+IFERROR(EF9*1,0)+IFERROR(ES9*1,0)+IFERROR(FF9*1,0) -> 0 | FQ9: =IFERROR(T9*1,0)+IFERROR(AG9*1,0)+IFERROR(AT9*1,0)+IFERROR(BG9*1,0)+IFERROR(BT9*1,0)+IFERROR(CG9*1,0)+IFERROR(CT9*1,0)+IFERROR(DG9*1,0)+IFERROR(DT9*1,0)+IFERROR(EG9*1,0)+IFERROR(ET9*1,0)+IFERROR(FG9*1,0) -> 0 | FR9: =IFERROR(U9*1,0)+IFERROR(AH9*1,0)+IFERROR(AU9*1,0)+IFERROR(BH9*1,0)+IFERROR(BU9*1,0)+IFERROR(CH9*1,0)+IFERROR(CU9*1,0)+IFERROR(DH9*1,0)+IFERROR(DU9*1,0)+IFERROR(EH9*1,0)+IFERROR(EU9*1,0)+IFERROR(FH9*1,0) -> 0 | FS9: =IFERROR(V9*1,0)+IFERROR(AI9*1,0)+IFERROR(AV9*1,0)+IFERROR(BI9*1,0)+IFERROR(BV9*1,0)+IFERROR(CI9*1,0)+IFERROR(CV9*1,0)+IFERROR(DI9*1,0)+IFERROR(DV9*1,0)+IFERROR(EI9*1,0)+IFERROR(EV9*1,0)+IFERROR(FI9*1,0) -> 0 | FT9: =IFERROR(W9*1,0)+IFERROR(AJ9*1,0)+IFERROR(AW9*1,0)+IFERROR(BJ9*1,0)+IFERROR(BW9*1,0)+IFERROR(CJ9*1,0)+IFERROR(CW9*1,0)+IFERROR(DJ9*1,0)+IFERROR(DW9*1,0)+IFERROR(EJ9*1,0)+IFERROR(EW9*1,0)+IFERROR(FJ9*1,0) -> 0 | FU9: =IFERROR(X9*1,0)+IFERROR(AK9*1,0)+IFERROR(AX9*1,0)+IFERROR(BK9*1,0)+IFERROR(BX9*1,0)+IFERROR(CK9*1,0)+IFERROR(CX9*1,0)+IFERROR(DK9*1,0)+IFERROR(DX9*1,0)+IFERROR(EK9*1,0)+IFERROR(EX9*1,0)+IFERROR(FK9*1,0) -> 0 | FV9: =IFERROR(Y9*1,0)+IFERROR(AL9*1,0)+IFERROR(AY9*1,0)+IFERROR(BL9*1,0)+IFERROR(BY9*1,0)+IFERROR(CL9*1,0)+IFERROR(CY9*1,0)+IFERROR(DL9*1,0)+IFERROR(DY9*1,0)+IFERROR(EL9*1,0)+IFERROR(EY9*1,0)+IFERROR(FL9*1,0) -> 0 | FX9: =N9+IFERROR(FW9*1,0) -> 0
A10: =IF(C10<>"","DRG-"&TEXT(7,"000"),"") -> DRG-007 | B10: Exception | C10: Exception | D10: Brunche | E10: هضبه ن | F10: Cairo | I10: 0.95833333 | L10: 4 | M10: =IF(N10>=4,"✔ Completed","✘ Pending") -> ✘ Pending | N10: =(P10="✔")+(AC10="✔")+(AP10="✔")+(BC10="✔")+(BP10="✔")+(CC10="✔")+(CP10="✔")+(DC10="✔")+(DP10="✔")+(EC10="✔")+(EP10="✔")+(FC10="✔") -> 0 | FO10: =IFERROR(R10*1,0)+IFERROR(AE10*1,0)+IFERROR(AR10*1,0)+IFERROR(BE10*1,0)+IFERROR(BR10*1,0)+IFERROR(CE10*1,0)+IFERROR(CR10*1,0)+IFERROR(DE10*1,0)+IFERROR(DR10*1,0)+IFERROR(EE10*1,0)+IFERROR(ER10*1,0)+IFERROR(FE10*1,0) -> 0 | FP10: =IFERROR(S10*1,0)+IFERROR(AF10*1,0)+IFERROR(AS10*1,0)+IFERROR(BF10*1,0)+IFERROR(BS10*1,0)+IFERROR(CF10*1,0)+IFERROR(CS10*1,0)+IFERROR(DF10*1,0)+IFERROR(DS10*1,0)+IFERROR(EF10*1,0)+IFERROR(ES10*1,0)+IFERROR(FF10*1,0) -> 0 | FQ10: =IFERROR(T10*1,0)+IFERROR(AG10*1,0)+IFERROR(AT10*1,0)+IFERROR(BG10*1,0)+IFERROR(BT10*1,0)+IFERROR(CG10*1,0)+IFERROR(CT10*1,0)+IFERROR(DG10*1,0)+IFERROR(DT10*1,0)+IFERROR(EG10*1,0)+IFERROR(ET10*1,0)+IFERROR(FG10*1,0) -> 0 | FR10: =IFERROR(U10*1,0)+IFERROR(AH10*1,0)+IFERROR(AU10*1,0)+IFERROR(BH10*1,0)+IFERROR(BU10*1,0)+IFERROR(CH10*1,0)+IFERROR(CU10*1,0)+IFERROR(DH10*1,0)+IFERROR(DU10*1,0)+IFERROR(EH10*1,0)+IFERROR(EU10*1,0)+IFERROR(FH10*1,0) -> 0 | FS10: =IFERROR(V10*1,0)+IFERROR(AI10*1,0)+IFERROR(AV10*1,0)+IFERROR(BI10*1,0)+IFERROR(BV10*1,0)+IFERROR(CI10*1,0)+IFERROR(CV10*1,0)+IFERROR(DI10*1,0)+IFERROR(DV10*1,0)+IFERROR(EI10*1,0)+IFERROR(EV10*1,0)+IFERROR(FI10*1,0) -> 0 | FT10: =IFERROR(W10*1,0)+IFERROR(AJ10*1,0)+IFERROR(AW10*1,0)+IFERROR(BJ10*1,0)+IFERROR(BW10*1,0)+IFERROR(CJ10*1,0)+IFERROR(CW10*1,0)+IFERROR(DJ10*1,0)+IFERROR(DW10*1,0)+IFERROR(EJ10*1,0)+IFERROR(EW10*1,0)+IFERROR(FJ10*1,0) -> 0 | FU10: =IFERROR(X10*1,0)+IFERROR(AK10*1,0)+IFERROR(AX10*1,0)+IFERROR(BK10*1,0)+IFERROR(BX10*1,0)+IFERROR(CK10*1,0)+IFERROR(CX10*1,0)+IFERROR(DK10*1,0)+IFERROR(DX10*1,0)+IFERROR(EK10*1,0)+IFERROR(EX10*1,0)+IFERROR(FK10*1,0) -> 0 | FV10: =IFERROR(Y10*1,0)+IFERROR(AL10*1,0)+IFERROR(AY10*1,0)+IFERROR(BL10*1,0)+IFERROR(BY10*1,0)+IFERROR(CL10*1,0)+IFERROR(CY10*1,0)+IFERROR(DL10*1,0)+IFERROR(DY10*1,0)+IFERROR(EL10*1,0)+IFERROR(EY10*1,0)+IFERROR(FL10*1,0) -> 0 | FX10: =N10+IFERROR(FW10*1,0) -> 0
A11: =IF(C11<>"","DRG-"&TEXT(8,"000"),"") -> DRG-008 | B11: Exception | C11: Exception | D11: Brunche | E11: هضبه س | F11: Cairo | I11: 0.95833333 | L11: 4 | M11: =IF(N11>=4,"✔ Completed","✘ Pending") -> ✘ Pending | N11: =(P11="✔")+(AC11="✔")+(AP11="✔")+(BC11="✔")+(BP11="✔")+(CC11="✔")+(CP11="✔")+(DC11="✔")+(DP11="✔")+(EC11="✔")+(EP11="✔")+(FC11="✔") -> 0 | FO11: =IFERROR(R11*1,0)+IFERROR(AE11*1,0)+IFERROR(AR11*1,0)+IFERROR(BE11*1,0)+IFERROR(BR11*1,0)+IFERROR(CE11*1,0)+IFERROR(CR11*1,0)+IFERROR(DE11*1,0)+IFERROR(DR11*1,0)+IFERROR(EE11*1,0)+IFERROR(ER11*1,0)+IFERROR(FE11*1,0) -> 0 | FP11: =IFERROR(S11*1,0)+IFERROR(AF11*1,0)+IFERROR(AS11*1,0)+IFERROR(BF11*1,0)+IFERROR(BS11*1,0)+IFERROR(CF11*1,0)+IFERROR(CS11*1,0)+IFERROR(DF11*1,0)+IFERROR(DS11*1,0)+IFERROR(EF11*1,0)+IFERROR(ES11*1,0)+IFERROR(FF11*1,0) -> 0 | FQ11: =IFERROR(T11*1,0)+IFERROR(AG11*1,0)+IFERROR(AT11*1,0)+IFERROR(BG11*1,0)+IFERROR(BT11*1,0)+IFERROR(CG11*1,0)+IFERROR(CT11*1,0)+IFERROR(DG11*1,0)+IFERROR(DT11*1,0)+IFERROR(EG11*1,0)+IFERROR(ET11*1,0)+IFERROR(FG11*1,0) -> 0 | FR11: =IFERROR(U11*1,0)+IFERROR(AH11*1,0)+IFERROR(AU11*1,0)+IFERROR(BH11*1,0)+IFERROR(BU11*1,0)+IFERROR(CH11*1,0)+IFERROR(CU11*1,0)+IFERROR(DH11*1,0)+IFERROR(DU11*1,0)+IFERROR(EH11*1,0)+IFERROR(EU11*1,0)+IFERROR(FH11*1,0) -> 0 | FS11: =IFERROR(V11*1,0)+IFERROR(AI11*1,0)+IFERROR(AV11*1,0)+IFERROR(BI11*1,0)+IFERROR(BV11*1,0)+IFERROR(CI11*1,0)+IFERROR(CV11*1,0)+IFERROR(DI11*1,0)+IFERROR(DV11*1,0)+IFERROR(EI11*1,0)+IFERROR(EV11*1,0)+IFERROR(FI11*1,0) -> 0 | FT11: =IFERROR(W11*1,0)+IFERROR(AJ11*1,0)+IFERROR(AW11*1,0)+IFERROR(BJ11*1,0)+IFERROR(BW11*1,0)+IFERROR(CJ11*1,0)+IFERROR(CW11*1,0)+IFERROR(DJ11*1,0)+IFERROR(DW11*1,0)+IFERROR(EJ11*1,0)+IFERROR(EW11*1,0)+IFERROR(FJ11*1,0) -> 0 | FU11: =IFERROR(X11*1,0)+IFERROR(AK11*1,0)+IFERROR(AX11*1,0)+IFERROR(BK11*1,0)+IFERROR(BX11*1,0)+IFERROR(CK11*1,0)+IFERROR(CX11*1,0)+IFERROR(DK11*1,0)+IFERROR(DX11*1,0)+IFERROR(EK11*1,0)+IFERROR(EX11*1,0)+IFERROR(FK11*1,0) -> 0 | FV11: =IFERROR(Y11*1,0)+IFERROR(AL11*1,0)+IFERROR(AY11*1,0)+IFERROR(BL11*1,0)+IFERROR(BY11*1,0)+IFERROR(CL11*1,0)+IFERROR(CY11*1,0)+IFERROR(DL11*1,0)+IFERROR(DY11*1,0)+IFERROR(EL11*1,0)+IFERROR(EY11*1,0)+IFERROR(FL11*1,0) -> 0 | FX11: =N11+IFERROR(FW11*1,0) -> 0
A12: =IF(C12<>"","DRG-"&TEXT(9,"000"),"") -> DRG-009 | B12: Exception | C12: Exception | D12: Brunche | E12: غرب سوميد | F12: Giza | G12: Sunday | I12: 0.95833333 | J12: 60min | K12: 4 | L12: 4 | M12: =IF(N12>=4,"✔ Completed","✘ Pending") -> ✘ Pending | N12: =(P12="✔")+(AC12="✔")+(AP12="✔")+(BC12="✔")+(BP12="✔")+(CC12="✔")+(CP12="✔")+(DC12="✔")+(DP12="✔")+(EC12="✔")+(EP12="✔")+(FC12="✔") -> 0 | FO12: =IFERROR(R12*1,0)+IFERROR(AE12*1,0)+IFERROR(AR12*1,0)+IFERROR(BE12*1,0)+IFERROR(BR12*1,0)+IFERROR(CE12*1,0)+IFERROR(CR12*1,0)+IFERROR(DE12*1,0)+IFERROR(DR12*1,0)+IFERROR(EE12*1,0)+IFERROR(ER12*1,0)+IFERROR(FE12*1,0) -> 0 | FP12: =IFERROR(S12*1,0)+IFERROR(AF12*1,0)+IFERROR(AS12*1,0)+IFERROR(BF12*1,0)+IFERROR(BS12*1,0)+IFERROR(CF12*1,0)+IFERROR(CS12*1,0)+IFERROR(DF12*1,0)+IFERROR(DS12*1,0)+IFERROR(EF12*1,0)+IFERROR(ES12*1,0)+IFERROR(FF12*1,0) -> 0 | FQ12: =IFERROR(T12*1,0)+IFERROR(AG12*1,0)+IFERROR(AT12*1,0)+IFERROR(BG12*1,0)+IFERROR(BT12*1,0)+IFERROR(CG12*1,0)+IFERROR(CT12*1,0)+IFERROR(DG12*1,0)+IFERROR(DT12*1,0)+IFERROR(EG12*1,0)+IFERROR(ET12*1,0)+IFERROR(FG12*1,0) -> 0 | FR12: =IFERROR(U12*1,0)+IFERROR(AH12*1,0)+IFERROR(AU12*1,0)+IFERROR(BH12*1,0)+IFERROR(BU12*1,0)+IFERROR(CH12*1,0)+IFERROR(CU12*1,0)+IFERROR(DH12*1,0)+IFERROR(DU12*1,0)+IFERROR(EH12*1,0)+IFERROR(EU12*1,0)+IFERROR(FH12*1,0) -> 0 | FS12: =IFERROR(V12*1,0)+IFERROR(AI12*1,0)+IFERROR(AV12*1,0)+IFERROR(BI12*1,0)+IFERROR(BV12*1,0)+IFERROR(CI12*1,0)+IFERROR(CV12*1,0)+IFERROR(DI12*1,0)+IFERROR(DV12*1,0)+IFERROR(EI12*1,0)+IFERROR(EV12*1,0)+IFERROR(FI12*1,0) -> 0 | FT12: =IFERROR(W12*1,0)+IFERROR(AJ12*1,0)+IFERROR(AW12*1,0)+IFERROR(BJ12*1,0)+IFERROR(BW12*1,0)+IFERROR(CJ12*1,0)+IFERROR(CW12*1,0)+IFERROR(DJ12*1,0)+IFERROR(DW12*1,0)+IFERROR(EJ12*1,0)+IFERROR(EW12*1,0)+IFERROR(FJ12*1,0) -> 0 | FU12: =IFERROR(X12*1,0)+IFERROR(AK12*1,0)+IFERROR(AX12*1,0)+IFERROR(BK12*1,0)+IFERROR(BX12*1,0)+IFERROR(CK12*1,0)+IFERROR(CX12*1,0)+IFERROR(DK12*1,0)+IFERROR(DX12*1,0)+IFERROR(EK12*1,0)+IFERROR(EX12*1,0)+IFERROR(FK12*1,0) -> 0 | FV12: =IFERROR(Y12*1,0)+IFERROR(AL12*1,0)+IFERROR(AY12*1,0)+IFERROR(BL12*1,0)+IFERROR(BY12*1,0)+IFERROR(CL12*1,0)+IFERROR(CY12*1,0)+IFERROR(DL12*1,0)+IFERROR(DY12*1,0)+IFERROR(EL12*1,0)+IFERROR(EY12*1,0)+IFERROR(FL12*1,0) -> 0 | FX12: =N12+IFERROR(FW12*1,0) -> 0
A13: =IF(C13<>"","DRG-"&TEXT(10,"000"),"") -> DRG-010 | B13: Exception | C13: Exception | D13: Brunche | E13: جمال عبد الناصر | F13: Giza | G13: Sunday | I13: 0.95833333 | J13: 60min | K13: 3 | L13: 4 | M13: =IF(N13>=4,"✔ Completed","✘ Pending") -> ✘ Pending | N13: =(P13="✔")+(AC13="✔")+(AP13="✔")+(BC13="✔")+(BP13="✔")+(CC13="✔")+(CP13="✔")+(DC13="✔")+(DP13="✔")+(EC13="✔")+(EP13="✔")+(FC13="✔") -> 0 | FO13: =IFERROR(R13*1,0)+IFERROR(AE13*1,0)+IFERROR(AR13*1,0)+IFERROR(BE13*1,0)+IFERROR(BR13*1,0)+IFERROR(CE13*1,0)+IFERROR(CR13*1,0)+IFERROR(DE13*1,0)+IFERROR(DR13*1,0)+IFERROR(EE13*1,0)+IFERROR(ER13*1,0)+IFERROR(FE13*1,0) -> 0 | FP13: =IFERROR(S13*1,0)+IFERROR(AF13*1,0)+IFERROR(AS13*1,0)+IFERROR(BF13*1,0)+IFERROR(BS13*1,0)+IFERROR(CF13*1,0)+IFERROR(CS13*1,0)+IFERROR(DF13*1,0)+IFERROR(DS13*1,0)+IFERROR(EF13*1,0)+IFERROR(ES13*1,0)+IFERROR(FF13*1,0) -> 0 | FQ13: =IFERROR(T13*1,0)+IFERROR(AG13*1,0)+IFERROR(AT13*1,0)+IFERROR(BG13*1,0)+IFERROR(BT13*1,0)+IFERROR(CG13*1,0)+IFERROR(CT13*1,0)+IFERROR(DG13*1,0)+IFERROR(DT13*1,0)+IFERROR(EG13*1,0)+IFERROR(ET13*1,0)+IFERROR(FG13*1,0) -> 0 | FR13: =IFERROR(U13*1,0)+IFERROR(AH13*1,0)+IFERROR(AU13*1,0)+IFERROR(BH13*1,0)+IFERROR(BU13*1,0)+IFERROR(CH13*1,0)+IFERROR(CU13*1,0)+IFERROR(DH13*1,0)+IFERROR(DU13*1,0)+IFERROR(EH13*1,0)+IFERROR(EU13*1,0)+IFERROR(FH13*1,0) -> 0 | FS13: =IFERROR(V13*1,0)+IFERROR(AI13*1,0)+IFERROR(AV13*1,0)+IFERROR(BI13*1,0)+IFERROR(BV13*1,0)+IFERROR(CI13*1,0)+IFERROR(CV13*1,0)+IFERROR(DI13*1,0)+IFERROR(DV13*1,0)+IFERROR(EI13*1,0)+IFERROR(EV13*1,0)+IFERROR(FI13*1,0) -> 0 | FT13: =IFERROR(W13*1,0)+IFERROR(AJ13*1,0)+IFERROR(AW13*1,0)+IFERROR(BJ13*1,0)+IFERROR(BW13*1,0)+IFERROR(CJ13*1,0)+IFERROR(CW13*1,0)+IFERROR(DJ13*1,0)+IFERROR(DW13*1,0)+IFERROR(EJ13*1,0)+IFERROR(EW13*1,0)+IFERROR(FJ13*1,0) -> 0 | FU13: =IFERROR(X13*1,0)+IFERROR(AK13*1,0)+IFERROR(AX13*1,0)+IFERROR(BK13*1,0)+IFERROR(BX13*1,0)+IFERROR(CK13*1,0)+IFERROR(CX13*1,0)+IFERROR(DK13*1,0)+IFERROR(DX13*1,0)+IFERROR(EK13*1,0)+IFERROR(EX13*1,0)+IFERROR(FK13*1,0) -> 0 | FV13: =IFERROR(Y13*1,0)+IFERROR(AL13*1,0)+IFERROR(AY13*1,0)+IFERROR(BL13*1,0)+IFERROR(BY13*1,0)+IFERROR(CL13*1,0)+IFERROR(CY13*1,0)+IFERROR(DL13*1,0)+IFERROR(DY13*1,0)+IFERROR(EL13*1,0)+IFERROR(EY13*1,0)+IFERROR(FL13*1,0) -> 0 | FX13: =N13+IFERROR(FW13*1,0) -> 0
A14: =IF(C14<>"","DRG-"&TEXT(11,"000"),"") -> DRG-011 | B14: Exception | C14: Exception | D14: Brunche | E14: زايد | F14: Giza | G14: Sunday | I14: 0.95833333 | J14: 60min | K14: 2 | L14: 4 | M14: =IF(N14>=4,"✔ Completed","✘ Pending") -> ✘ Pending | N14: =(P14="✔")+(AC14="✔")+(AP14="✔")+(BC14="✔")+(BP14="✔")+(CC14="✔")+(CP14="✔")+(DC14="✔")+(DP14="✔")+(EC14="✔")+(EP14="✔")+(FC14="✔") -> 0 | FO14: =IFERROR(R14*1,0)+IFERROR(AE14*1,0)+IFERROR(AR14*1,0)+IFERROR(BE14*1,0)+IFERROR(BR14*1,0)+IFERROR(CE14*1,0)+IFERROR(CR14*1,0)+IFERROR(DE14*1,0)+IFERROR(DR14*1,0)+IFERROR(EE14*1,0)+IFERROR(ER14*1,0)+IFERROR(FE14*1,0) -> 0 | FP14: =IFERROR(S14*1,0)+IFERROR(AF14*1,0)+IFERROR(AS14*1,0)+IFERROR(BF14*1,0)+IFERROR(BS14*1,0)+IFERROR(CF14*1,0)+IFERROR(CS14*1,0)+IFERROR(DF14*1,0)+IFERROR(DS14*1,0)+IFERROR(EF14*1,0)+IFERROR(ES14*1,0)+IFERROR(FF14*1,0) -> 0 | FQ14: =IFERROR(T14*1,0)+IFERROR(AG14*1,0)+IFERROR(AT14*1,0)+IFERROR(BG14*1,0)+IFERROR(BT14*1,0)+IFERROR(CG14*1,0)+IFERROR(CT14*1,0)+IFERROR(DG14*1,0)+IFERROR(DT14*1,0)+IFERROR(EG14*1,0)+IFERROR(ET14*1,0)+IFERROR(FG14*1,0) -> 0 | FR14: =IFERROR(U14*1,0)+IFERROR(AH14*1,0)+IFERROR(AU14*1,0)+IFERROR(BH14*1,0)+IFERROR(BU14*1,0)+IFERROR(CH14*1,0)+IFERROR(CU14*1,0)+IFERROR(DH14*1,0)+IFERROR(DU14*1,0)+IFERROR(EH14*1,0)+IFERROR(EU14*1,0)+IFERROR(FH14*1,0) -> 0 | FS14: =IFERROR(V14*1,0)+IFERROR(AI14*1,0)+IFERROR(AV14*1,0)+IFERROR(BI14*1,0)+IFERROR(BV14*1,0)+IFERROR(CI14*1,0)+IFERROR(CV14*1,0)+IFERROR(DI14*1,0)+IFERROR(DV14*1,0)+IFERROR(EI14*1,0)+IFERROR(EV14*1,0)+IFERROR(FI14*1,0) -> 0 | FT14: =IFERROR(W14*1,0)+IFERROR(AJ14*1,0)+IFERROR(AW14*1,0)+IFERROR(BJ14*1,0)+IFERROR(BW14*1,0)+IFERROR(CJ14*1,0)+IFERROR(CW14*1,0)+IFERROR(DJ14*1,0)+IFERROR(DW14*1,0)+IFERROR(EJ14*1,0)+IFERROR(EW14*1,0)+IFERROR(FJ14*1,0) -> 0 | FU14: =IFERROR(X14*1,0)+IFERROR(AK14*1,0)+IFERROR(AX14*1,0)+IFERROR(BK14*1,0)+IFERROR(BX14*1,0)+IFERROR(CK14*1,0)+IFERROR(CX14*1,0)+IFERROR(DK14*1,0)+IFERROR(DX14*1,0)+IFERROR(EK14*1,0)+IFERROR(EX14*1,0)+IFERROR(FK14*1,0) -> 0 | FV14: =IFERROR(Y14*1,0)+IFERROR(AL14*1,0)+IFERROR(AY14*1,0)+IFERROR(BL14*1,0)+IFERROR(BY14*1,0)+IFERROR(CL14*1,0)+IFERROR(CY14*1,0)+IFERROR(DL14*1,0)+IFERROR(DY14*1,0)+IFERROR(EL14*1,0)+IFERROR(EY14*1,0)+IFERROR(FL14*1,0) -> 0 | FX14: =N14+IFERROR(FW14*1,0) -> 0
A15: =IF(C15<>"","DRG-"&TEXT(12,"000"),"") -> DRG-012 | B15: Exception | C15: Exception | D15: Brunche | E15: الحصري | F15: Giza | G15: Sunday | I15: 0.95833333 | J15: 60min | K15: 2 | L15: 4 | M15: =IF(N15>=4,"✔ Completed","✘ Pending") -> ✘ Pending | N15: =(P15="✔")+(AC15="✔")+(AP15="✔")+(BC15="✔")+(BP15="✔")+(CC15="✔")+(CP15="✔")+(DC15="✔")+(DP15="✔")+(EC15="✔")+(EP15="✔")+(FC15="✔") -> 0 | FO15: =IFERROR(R15*1,0)+IFERROR(AE15*1,0)+IFERROR(AR15*1,0)+IFERROR(BE15*1,0)+IFERROR(BR15*1,0)+IFERROR(CE15*1,0)+IFERROR(CR15*1,0)+IFERROR(DE15*1,0)+IFERROR(DR15*1,0)+IFERROR(EE15*1,0)+IFERROR(ER15*1,0)+IFERROR(FE15*1,0) -> 0 | FP15: =IFERROR(S15*1,0)+IFERROR(AF15*1,0)+IFERROR(AS15*1,0)+IFERROR(BF15*1,0)+IFERROR(BS15*1,0)+IFERROR(CF15*1,0)+IFERROR(CS15*1,0)+IFERROR(DF15*1,0)+IFERROR(DS15*1,0)+IFERROR(EF15*1,0)+IFERROR(ES15*1,0)+IFERROR(FF15*1,0) -> 0 | FQ15: =IFERROR(T15*1,0)+IFERROR(AG15*1,0)+IFERROR(AT15*1,0)+IFERROR(BG15*1,0)+IFERROR(BT15*1,0)+IFERROR(CG15*1,0)+IFERROR(CT15*1,0)+IFERROR(DG15*1,0)+IFERROR(DT15*1,0)+IFERROR(EG15*1,0)+IFERROR(ET15*1,0)+IFERROR(FG15*1,0) -> 0 | FR15: =IFERROR(U15*1,0)+IFERROR(AH15*1,0)+IFERROR(AU15*1,0)+IFERROR(BH15*1,0)+IFERROR(BU15*1,0)+IFERROR(CH15*1,0)+IFERROR(CU15*1,0)+IFERROR(DH15*1,0)+IFERROR(DU15*1,0)+IFERROR(EH15*1,0)+IFERROR(EU15*1,0)+IFERROR(FH15*1,0) -> 0 | FS15: =IFERROR(V15*1,0)+IFERROR(AI15*1,0)+IFERROR(AV15*1,0)+IFERROR(BI15*1,0)+IFERROR(BV15*1,0)+IFERROR(CI15*1,0)+IFERROR(CV15*1,0)+IFERROR(DI15*1,0)+IFERROR(DV15*1,0)+IFERROR(EI15*1,0)+IFERROR(EV15*1,0)+IFERROR(FI15*1,0) -> 0 | FT15: =IFERROR(W15*1,0)+IFERROR(AJ15*1,0)+IFERROR(AW15*1,0)+IFERROR(BJ15*1,0)+IFERROR(BW15*1,0)+IFERROR(CJ15*1,0)+IFERROR(CW15*1,0)+IFERROR(DJ15*1,0)+IFERROR(DW15*1,0)+IFERROR(EJ15*1,0)+IFERROR(EW15*1,0)+IFERROR(FJ15*1,0) -> 0 | FU15: =IFERROR(X15*1,0)+IFERROR(AK15*1,0)+IFERROR(AX15*1,0)+IFERROR(BK15*1,0)+IFERROR(BX15*1,0)+IFERROR(CK15*1,0)+IFERROR(CX15*1,0)+IFERROR(DK15*1,0)+IFERROR(DX15*1,0)+IFERROR(EK15*1,0)+IFERROR(EX15*1,0)+IFERROR(FK15*1,0) -> 0 | FV15: =IFERROR(Y15*1,0)+IFERROR(AL15*1,0)+IFERROR(AY15*1,0)+IFERROR(BL15*1,0)+IFERROR(BY15*1,0)+IFERROR(CL15*1,0)+IFERROR(CY15*1,0)+IFERROR(DL15*1,0)+IFERROR(DY15*1,0)+IFERROR(EL15*1,0)+IFERROR(EY15*1,0)+IFERROR(FL15*1,0) -> 0 | FX15: =N15+IFERROR(FW15*1,0) -> 0
A16: =IF(C16<>"","DRG-"&TEXT(13,"000"),"") -> DRG-013 | B16: Exception | C16: Exception | D16: Brunche | E16: الفيوم | F16: Fayoum | I16: 0.95833333 | L16: 4 | M16: =IF(N16>=4,"✔ Completed","✘ Pending") -> ✘ Pending | N16: =(P16="✔")+(AC16="✔")+(AP16="✔")+(BC16="✔")+(BP16="✔")+(CC16="✔")+(CP16="✔")+(DC16="✔")+(DP16="✔")+(EC16="✔")+(EP16="✔")+(FC16="✔") -> 0 | FO16: =IFERROR(R16*1,0)+IFERROR(AE16*1,0)+IFERROR(AR16*1,0)+IFERROR(BE16*1,0)+IFERROR(BR16*1,0)+IFERROR(CE16*1,0)+IFERROR(CR16*1,0)+IFERROR(DE16*1,0)+IFERROR(DR16*1,0)+IFERROR(EE16*1,0)+IFERROR(ER16*1,0)+IFERROR(FE16*1,0) -> 0 | FP16: =IFERROR(S16*1,0)+IFERROR(AF16*1,0)+IFERROR(AS16*1,0)+IFERROR(BF16*1,0)+IFERROR(BS16*1,0)+IFERROR(CF16*1,0)+IFERROR(CS16*1,0)+IFERROR(DF16*1,0)+IFERROR(DS16*1,0)+IFERROR(EF16*1,0)+IFERROR(ES16*1,0)+IFERROR(FF16*1,0) -> 0 | FQ16: =IFERROR(T16*1,0)+IFERROR(AG16*1,0)+IFERROR(AT16*1,0)+IFERROR(BG16*1,0)+IFERROR(BT16*1,0)+IFERROR(CG16*1,0)+IFERROR(CT16*1,0)+IFERROR(DG16*1,0)+IFERROR(DT16*1,0)+IFERROR(EG16*1,0)+IFERROR(ET16*1,0)+IFERROR(FG16*1,0) -> 0 | FR16: =IFERROR(U16*1,0)+IFERROR(AH16*1,0)+IFERROR(AU16*1,0)+IFERROR(BH16*1,0)+IFERROR(BU16*1,0)+IFERROR(CH16*1,0)+IFERROR(CU16*1,0)+IFERROR(DH16*1,0)+IFERROR(DU16*1,0)+IFERROR(EH16*1,0)+IFERROR(EU16*1,0)+IFERROR(FH16*1,0) -> 0 | FS16: =IFERROR(V16*1,0)+IFERROR(AI16*1,0)+IFERROR(AV16*1,0)+IFERROR(BI16*1,0)+IFERROR(BV16*1,0)+IFERROR(CI16*1,0)+IFERROR(CV16*1,0)+IFERROR(DI16*1,0)+IFERROR(DV16*1,0)+IFERROR(EI16*1,0)+IFERROR(EV16*1,0)+IFERROR(FI16*1,0) -> 0 | FT16: =IFERROR(W16*1,0)+IFERROR(AJ16*1,0)+IFERROR(AW16*1,0)+IFERROR(BJ16*1,0)+IFERROR(BW16*1,0)+IFERROR(CJ16*1,0)+IFERROR(CW16*1,0)+IFERROR(DJ16*1,0)+IFERROR(DW16*1,0)+IFERROR(EJ16*1,0)+IFERROR(EW16*1,0)+IFERROR(FJ16*1,0) -> 0 | FU16: =IFERROR(X16*1,0)+IFERROR(AK16*1,0)+IFERROR(AX16*1,0)+IFERROR(BK16*1,0)+IFERROR(BX16*1,0)+IFERROR(CK16*1,0)+IFERROR(CX16*1,0)+IFERROR(DK16*1,0)+IFERROR(DX16*1,0)+IFERROR(EK16*1,0)+IFERROR(EX16*1,0)+IFERROR(FK16*1,0) -> 0 | FV16: =IFERROR(Y16*1,0)+IFERROR(AL16*1,0)+IFERROR(AY16*1,0)+IFERROR(BL16*1,0)+IFERROR(BY16*1,0)+IFERROR(CL16*1,0)+IFERROR(CY16*1,0)+IFERROR(DL16*1,0)+IFERROR(DY16*1,0)+IFERROR(EL16*1,0)+IFERROR(EY16*1,0)+IFERROR(FL16*1,0) -> 0 | FX16: =N16+IFERROR(FW16*1,0) -> 0
A17: =IF(C17<>"","DRG-"&TEXT(14,"000"),"") -> DRG-014 | B17: Exception | C17: Exception | D17: Brunche | E17: جامعه MSA | F17: Giza | I17: 0.95833333 | L17: 4 | M17: =IF(N17>=4,"✔ Completed","✘ Pending") -> ✘ Pending | N17: =(P17="✔")+(AC17="✔")+(AP17="✔")+(BC17="✔")+(BP17="✔")+(CC17="✔")+(CP17="✔")+(DC17="✔")+(DP17="✔")+(EC17="✔")+(EP17="✔")+(FC17="✔") -> 0 | FO17: =IFERROR(R17*1,0)+IFERROR(AE17*1,0)+IFERROR(AR17*1,0)+IFERROR(BE17*1,0)+IFERROR(BR17*1,0)+IFERROR(CE17*1,0)+IFERROR(CR17*1,0)+IFERROR(DE17*1,0)+IFERROR(DR17*1,0)+IFERROR(EE17*1,0)+IFERROR(ER17*1,0)+IFERROR(FE17*1,0) -> 0 | FP17: =IFERROR(S17*1,0)+IFERROR(AF17*1,0)+IFERROR(AS17*1,0)+IFERROR(BF17*1,0)+IFERROR(BS17*1,0)+IFERROR(CF17*1,0)+IFERROR(CS17*1,0)+IFERROR(DF17*1,0)+IFERROR(DS17*1,0)+IFERROR(EF17*1,0)+IFERROR(ES17*1,0)+IFERROR(FF17*1,0) -> 0 | FQ17: =IFERROR(T17*1,0)+IFERROR(AG17*1,0)+IFERROR(AT17*1,0)+IFERROR(BG17*1,0)+IFERROR(BT17*1,0)+IFERROR(CG17*1,0)+IFERROR(CT17*1,0)+IFERROR(DG17*1,0)+IFERROR(DT17*1,0)+IFERROR(EG17*1,0)+IFERROR(ET17*1,0)+IFERROR(FG17*1,0) -> 0 | FR17: =IFERROR(U17*1,0)+IFERROR(AH17*1,0)+IFERROR(AU17*1,0)+IFERROR(BH17*1,0)+IFERROR(BU17*1,0)+IFERROR(CH17*1,0)+IFERROR(CU17*1,0)+IFERROR(DH17*1,0)+IFERROR(DU17*1,0)+IFERROR(EH17*1,0)+IFERROR(EU17*1,0)+IFERROR(FH17*1,0) -> 0 | FS17: =IFERROR(V17*1,0)+IFERROR(AI17*1,0)+IFERROR(AV17*1,0)+IFERROR(BI17*1,0)+IFERROR(BV17*1,0)+IFERROR(CI17*1,0)+IFERROR(CV17*1,0)+IFERROR(DI17*1,0)+IFERROR(DV17*1,0)+IFERROR(EI17*1,0)+IFERROR(EV17*1,0)+IFERROR(FI17*1,0) -> 0 | FT17: =IFERROR(W17*1,0)+IFERROR(AJ17*1,0)+IFERROR(AW17*1,0)+IFERROR(BJ17*1,0)+IFERROR(BW17*1,0)+IFERROR(CJ17*1,0)+IFERROR(CW17*1,0)+IFERROR(DJ17*1,0)+IFERROR(DW17*1,0)+IFERROR(EJ17*1,0)+IFERROR(EW17*1,0)+IFERROR(FJ17*1,0) -> 0 | FU17: =IFERROR(X17*1,0)+IFERROR(AK17*1,0)+IFERROR(AX17*1,0)+IFERROR(BK17*1,0)+IFERROR(BX17*1,0)+IFERROR(CK17*1,0)+IFERROR(CX17*1,0)+IFERROR(DK17*1,0)+IFERROR(DX17*1,0)+IFERROR(EK17*1,0)+IFERROR(EX17*1,0)+IFERROR(FK17*1,0) -> 0 | FV17: =IFERROR(Y17*1,0)+IFERROR(AL17*1,0)+IFERROR(AY17*1,0)+IFERROR(BL17*1,0)+IFERROR(BY17*1,0)+IFERROR(CL17*1,0)+IFERROR(CY17*1,0)+IFERROR(DL17*1,0)+IFERROR(DY17*1,0)+IFERROR(EL17*1,0)+IFERROR(EY17*1,0)+IFERROR(FL17*1,0) -> 0 | FX17: =N17+IFERROR(FW17*1,0) -> 0
A18: =IF(C18<>"","DRG-"&TEXT(15,"000"),"") -> DRG-015 | B18: Exception | C18: Exception | D18: Brunche | E18: المهندسين | F18: Giza | L18: 4 | M18: =IF(N18>=4,"✔ Completed","✘ Pending") -> ✘ Pending | N18: =(P18="✔")+(AC18="✔")+(AP18="✔")+(BC18="✔")+(BP18="✔")+(CC18="✔")+(CP18="✔")+(DC18="✔")+(DP18="✔")+(EC18="✔")+(EP18="✔")+(FC18="✔") -> 0 | FO18: =IFERROR(R18*1,0)+IFERROR(AE18*1,0)+IFERROR(AR18*1,0)+IFERROR(BE18*1,0)+IFERROR(BR18*1,0)+IFERROR(CE18*1,0)+IFERROR(CR18*1,0)+IFERROR(DE18*1,0)+IFERROR(DR18*1,0)+IFERROR(EE18*1,0)+IFERROR(ER18*1,0)+IFERROR(FE18*1,0) -> 0 | FP18: =IFERROR(S18*1,0)+IFERROR(AF18*1,0)+IFERROR(AS18*1,0)+IFERROR(BF18*1,0)+IFERROR(BS18*1,0)+IFERROR(CF18*1,0)+IFERROR(CS18*1,0)+IFERROR(DF18*1,0)+IFERROR(DS18*1,0)+IFERROR(EF18*1,0)+IFERROR(ES18*1,0)+IFERROR(FF18*1,0) -> 0 | FQ18: =IFERROR(T18*1,0)+IFERROR(AG18*1,0)+IFERROR(AT18*1,0)+IFERROR(BG18*1,0)+IFERROR(BT18*1,0)+IFERROR(CG18*1,0)+IFERROR(CT18*1,0)+IFERROR(DG18*1,0)+IFERROR(DT18*1,0)+IFERROR(EG18*1,0)+IFERROR(ET18*1,0)+IFERROR(FG18*1,0) -> 0 | FR18: =IFERROR(U18*1,0)+IFERROR(AH18*1,0)+IFERROR(AU18*1,0)+IFERROR(BH18*1,0)+IFERROR(BU18*1,0)+IFERROR(CH18*1,0)+IFERROR(CU18*1,0)+IFERROR(DH18*1,0)+IFERROR(DU18*1,0)+IFERROR(EH18*1,0)+IFERROR(EU18*1,0)+IFERROR(FH18*1,0) -> 0 | FS18: =IFERROR(V18*1,0)+IFERROR(AI18*1,0)+IFERROR(AV18*1,0)+IFERROR(BI18*1,0)+IFERROR(BV18*1,0)+IFERROR(CI18*1,0)+IFERROR(CV18*1,0)+IFERROR(DI18*1,0)+IFERROR(DV18*1,0)+IFERROR(EI18*1,0)+IFERROR(EV18*1,0)+IFERROR(FI18*1,0) -> 0 | FT18: =IFERROR(W18*1,0)+IFERROR(AJ18*1,0)+IFERROR(AW18*1,0)+IFERROR(BJ18*1,0)+IFERROR(BW18*1,0)+IFERROR(CJ18*1,0)+IFERROR(CW18*1,0)+IFERROR(DJ18*1,0)+IFERROR(DW18*1,0)+IFERROR(EJ18*1,0)+IFERROR(EW18*1,0)+IFERROR(FJ18*1,0) -> 0 | FU18: =IFERROR(X18*1,0)+IFERROR(AK18*1,0)+IFERROR(AX18*1,0)+IFERROR(BK18*1,0)+IFERROR(BX18*1,0)+IFERROR(CK18*1,0)+IFERROR(CX18*1,0)+IFERROR(DK18*1,0)+IFERROR(DX18*1,0)+IFERROR(EK18*1,0)+IFERROR(EX18*1,0)+IFERROR(FK18*1,0) -> 0 | FV18: =IFERROR(Y18*1,0)+IFERROR(AL18*1,0)+IFERROR(AY18*1,0)+IFERROR(BL18*1,0)+IFERROR(BY18*1,0)+IFERROR(CL18*1,0)+IFERROR(CY18*1,0)+IFERROR(DL18*1,0)+IFERROR(DY18*1,0)+IFERROR(EL18*1,0)+IFERROR(EY18*1,0)+IFERROR(FL18*1,0) -> 0 | FX18: =N18+IFERROR(FW18*1,0) -> 0
A19: =IF(C19<>"","DRG-"&TEXT(16,"000"),"") -> DRG-016 | B19: Exception | C19: Exception | D19: Brunche | E19: معادي لاسيلكي | F19: Cairo | L19: 4 | M19: =IF(N19>=4,"✔ Completed","✘ Pending") -> ✘ Pending | N19: =(P19="✔")+(AC19="✔")+(AP19="✔")+(BC19="✔")+(BP19="✔")+(CC19="✔")+(CP19="✔")+(DC19="✔")+(DP19="✔")+(EC19="✔")+(EP19="✔")+(FC19="✔") -> 0 | FO19: =IFERROR(R19*1,0)+IFERROR(AE19*1,0)+IFERROR(AR19*1,0)+IFERROR(BE19*1,0)+IFERROR(BR19*1,0)+IFERROR(CE19*1,0)+IFERROR(CR19*1,0)+IFERROR(DE19*1,0)+IFERROR(DR19*1,0)+IFERROR(EE19*1,0)+IFERROR(ER19*1,0)+IFERROR(FE19*1,0) -> 0 | FP19: =IFERROR(S19*1,0)+IFERROR(AF19*1,0)+IFERROR(AS19*1,0)+IFERROR(BF19*1,0)+IFERROR(BS19*1,0)+IFERROR(CF19*1,0)+IFERROR(CS19*1,0)+IFERROR(DF19*1,0)+IFERROR(DS19*1,0)+IFERROR(EF19*1,0)+IFERROR(ES19*1,0)+IFERROR(FF19*1,0) -> 0 | FQ19: =IFERROR(T19*1,0)+IFERROR(AG19*1,0)+IFERROR(AT19*1,0)+IFERROR(BG19*1,0)+IFERROR(BT19*1,0)+IFERROR(CG19*1,0)+IFERROR(CT19*1,0)+IFERROR(DG19*1,0)+IFERROR(DT19*1,0)+IFERROR(EG19*1,0)+IFERROR(ET19*1,0)+IFERROR(FG19*1,0) -> 0 | FR19: =IFERROR(U19*1,0)+IFERROR(AH19*1,0)+IFERROR(AU19*1,0)+IFERROR(BH19*1,0)+IFERROR(BU19*1,0)+IFERROR(CH19*1,0)+IFERROR(CU19*1,0)+IFERROR(DH19*1,0)+IFERROR(DU19*1,0)+IFERROR(EH19*1,0)+IFERROR(EU19*1,0)+IFERROR(FH19*1,0) -> 0 | FS19: =IFERROR(V19*1,0)+IFERROR(AI19*1,0)+IFERROR(AV19*1,0)+IFERROR(BI19*1,0)+IFERROR(BV19*1,0)+IFERROR(CI19*1,0)+IFERROR(CV19*1,0)+IFERROR(DI19*1,0)+IFERROR(DV19*1,0)+IFERROR(EI19*1,0)+IFERROR(EV19*1,0)+IFERROR(FI19*1,0) -> 0 | FT19: =IFERROR(W19*1,0)+IFERROR(AJ19*1,0)+IFERROR(AW19*1,0)+IFERROR(BJ19*1,0)+IFERROR(BW19*1,0)+IFERROR(CJ19*1,0)+IFERROR(CW19*1,0)+IFERROR(DJ19*1,0)+IFERROR(DW19*1,0)+IFERROR(EJ19*1,0)+IFERROR(EW19*1,0)+IFERROR(FJ19*1,0) -> 0 | FU19: =IFERROR(X19*1,0)+IFERROR(AK19*1,0)+IFERROR(AX19*1,0)+IFERROR(BK19*1,0)+IFERROR(BX19*1,0)+IFERROR(CK19*1,0)+IFERROR(CX19*1,0)+IFERROR(DK19*1,0)+IFERROR(DX19*1,0)+IFERROR(EK19*1,0)+IFERROR(EX19*1,0)+IFERROR(FK19*1,0) -> 0 | FV19: =IFERROR(Y19*1,0)+IFERROR(AL19*1,0)+IFERROR(AY19*1,0)+IFERROR(BL19*1,0)+IFERROR(BY19*1,0)+IFERROR(CL19*1,0)+IFERROR(CY19*1,0)+IFERROR(DL19*1,0)+IFERROR(DY19*1,0)+IFERROR(EL19*1,0)+IFERROR(EY19*1,0)+IFERROR(FL19*1,0) -> 0 | FX19: =N19+IFERROR(FW19*1,0) -> 0
A20: =IF(C20<>"","DRG-"&TEXT(17,"000"),"") -> DRG-017 | B20: Exception | C20: Exception | D20: Brunche | E20: معادي بيتشو | F20: Cairo | L20: 4 | M20: =IF(N20>=4,"✔ Completed","✘ Pending") -> ✘ Pending | N20: =(P20="✔")+(AC20="✔")+(AP20="✔")+(BC20="✔")+(BP20="✔")+(CC20="✔")+(CP20="✔")+(DC20="✔")+(DP20="✔")+(EC20="✔")+(EP20="✔")+(FC20="✔") -> 0 | FO20: =IFERROR(R20*1,0)+IFERROR(AE20*1,0)+IFERROR(AR20*1,0)+IFERROR(BE20*1,0)+IFERROR(BR20*1,0)+IFERROR(CE20*1,0)+IFERROR(CR20*1,0)+IFERROR(DE20*1,0)+IFERROR(DR20*1,0)+IFERROR(EE20*1,0)+IFERROR(ER20*1,0)+IFERROR(FE20*1,0) -> 0 | FP20: =IFERROR(S20*1,0)+IFERROR(AF20*1,0)+IFERROR(AS20*1,0)+IFERROR(BF20*1,0)+IFERROR(BS20*1,0)+IFERROR(CF20*1,0)+IFERROR(CS20*1,0)+IFERROR(DF20*1,0)+IFERROR(DS20*1,0)+IFERROR(EF20*1,0)+IFERROR(ES20*1,0)+IFERROR(FF20*1,0) -> 0 | FQ20: =IFERROR(T20*1,0)+IFERROR(AG20*1,0)+IFERROR(AT20*1,0)+IFERROR(BG20*1,0)+IFERROR(BT20*1,0)+IFERROR(CG20*1,0)+IFERROR(CT20*1,0)+IFERROR(DG20*1,0)+IFERROR(DT20*1,0)+IFERROR(EG20*1,0)+IFERROR(ET20*1,0)+IFERROR(FG20*1,0) -> 0 | FR20: =IFERROR(U20*1,0)+IFERROR(AH20*1,0)+IFERROR(AU20*1,0)+IFERROR(BH20*1,0)+IFERROR(BU20*1,0)+IFERROR(CH20*1,0)+IFERROR(CU20*1,0)+IFERROR(DH20*1,0)+IFERROR(DU20*1,0)+IFERROR(EH20*1,0)+IFERROR(EU20*1,0)+IFERROR(FH20*1,0) -> 0 | FS20: =IFERROR(V20*1,0)+IFERROR(AI20*1,0)+IFERROR(AV20*1,0)+IFERROR(BI20*1,0)+IFERROR(BV20*1,0)+IFERROR(CI20*1,0)+IFERROR(CV20*1,0)+IFERROR(DI20*1,0)+IFERROR(DV20*1,0)+IFERROR(EI20*1,0)+IFERROR(EV20*1,0)+IFERROR(FI20*1,0) -> 0 | FT20: =IFERROR(W20*1,0)+IFERROR(AJ20*1,0)+IFERROR(AW20*1,0)+IFERROR(BJ20*1,0)+IFERROR(BW20*1,0)+IFERROR(CJ20*1,0)+IFERROR(CW20*1,0)+IFERROR(DJ20*1,0)+IFERROR(DW20*1,0)+IFERROR(EJ20*1,0)+IFERROR(EW20*1,0)+IFERROR(FJ20*1,0) -> 0 | FU20: =IFERROR(X20*1,0)+IFERROR(AK20*1,0)+IFERROR(AX20*1,0)+IFERROR(BK20*1,0)+IFERROR(BX20*1,0)+IFERROR(CK20*1,0)+IFERROR(CX20*1,0)+IFERROR(DK20*1,0)+IFERROR(DX20*1,0)+IFERROR(EK20*1,0)+IFERROR(EX20*1,0)+IFERROR(FK20*1,0) -> 0 | FV20: =IFERROR(Y20*1,0)+IFERROR(AL20*1,0)+IFERROR(AY20*1,0)+IFERROR(BL20*1,0)+IFERROR(BY20*1,0)+IFERROR(CL20*1,0)+IFERROR(CY20*1,0)+IFERROR(DL20*1,0)+IFERROR(DY20*1,0)+IFERROR(EL20*1,0)+IFERROR(EY20*1,0)+IFERROR(FL20*1,0) -> 0 | FX20: =N20+IFERROR(FW20*1,0) -> 0
A21: =IF(C21<>"","DRG-"&TEXT(18,"000"),"") -> DRG-018 | B21: Exception | C21: Exception | D21: Brunche | E21: معادي دائري | F21: Cairo | L21: 4 | M21: =IF(N21>=4,"✔ Completed","✘ Pending") -> ✘ Pending | N21: =(P21="✔")+(AC21="✔")+(AP21="✔")+(BC21="✔")+(BP21="✔")+(CC21="✔")+(CP21="✔")+(DC21="✔")+(DP21="✔")+(EC21="✔")+(EP21="✔")+(FC21="✔") -> 0 | FO21: =IFERROR(R21*1,0)+IFERROR(AE21*1,0)+IFERROR(AR21*1,0)+IFERROR(BE21*1,0)+IFERROR(BR21*1,0)+IFERROR(CE21*1,0)+IFERROR(CR21*1,0)+IFERROR(DE21*1,0)+IFERROR(DR21*1,0)+IFERROR(EE21*1,0)+IFERROR(ER21*1,0)+IFERROR(FE21*1,0) -> 0 | FP21: =IFERROR(S21*1,0)+IFERROR(AF21*1,0)+IFERROR(AS21*1,0)+IFERROR(BF21*1,0)+IFERROR(BS21*1,0)+IFERROR(CF21*1,0)+IFERROR(CS21*1,0)+IFERROR(DF21*1,0)+IFERROR(DS21*1,0)+IFERROR(EF21*1,0)+IFERROR(ES21*1,0)+IFERROR(FF21*1,0) -> 0 | FQ21: =IFERROR(T21*1,0)+IFERROR(AG21*1,0)+IFERROR(AT21*1,0)+IFERROR(BG21*1,0)+IFERROR(BT21*1,0)+IFERROR(CG21*1,0)+IFERROR(CT21*1,0)+IFERROR(DG21*1,0)+IFERROR(DT21*1,0)+IFERROR(EG21*1,0)+IFERROR(ET21*1,0)+IFERROR(FG21*1,0) -> 0 | FR21: =IFERROR(U21*1,0)+IFERROR(AH21*1,0)+IFERROR(AU21*1,0)+IFERROR(BH21*1,0)+IFERROR(BU21*1,0)+IFERROR(CH21*1,0)+IFERROR(CU21*1,0)+IFERROR(DH21*1,0)+IFERROR(DU21*1,0)+IFERROR(EH21*1,0)+IFERROR(EU21*1,0)+IFERROR(FH21*1,0) -> 0 | FS21: =IFERROR(V21*1,0)+IFERROR(AI21*1,0)+IFERROR(AV21*1,0)+IFERROR(BI21*1,0)+IFERROR(BV21*1,0)+IFERROR(CI21*1,0)+IFERROR(CV21*1,0)+IFERROR(DI21*1,0)+IFERROR(DV21*1,0)+IFERROR(EI21*1,0)+IFERROR(EV21*1,0)+IFERROR(FI21*1,0) -> 0 | FT21: =IFERROR(W21*1,0)+IFERROR(AJ21*1,0)+IFERROR(AW21*1,0)+IFERROR(BJ21*1,0)+IFERROR(BW21*1,0)+IFERROR(CJ21*1,0)+IFERROR(CW21*1,0)+IFERROR(DJ21*1,0)+IFERROR(DW21*1,0)+IFERROR(EJ21*1,0)+IFERROR(EW21*1,0)+IFERROR(FJ21*1,0) -> 0 | FU21: =IFERROR(X21*1,0)+IFERROR(AK21*1,0)+IFERROR(AX21*1,0)+IFERROR(BK21*1,0)+IFERROR(BX21*1,0)+IFERROR(CK21*1,0)+IFERROR(CX21*1,0)+IFERROR(DK21*1,0)+IFERROR(DX21*1,0)+IFERROR(EK21*1,0)+IFERROR(EX21*1,0)+IFERROR(FK21*1,0) -> 0 | FV21: =IFERROR(Y21*1,0)+IFERROR(AL21*1,0)+IFERROR(AY21*1,0)+IFERROR(BL21*1,0)+IFERROR(BY21*1,0)+IFERROR(CL21*1,0)+IFERROR(CY21*1,0)+IFERROR(DL21*1,0)+IFERROR(DY21*1,0)+IFERROR(EL21*1,0)+IFERROR(EY21*1,0)+IFERROR(FL21*1,0) -> 0 | FX21: =N21+IFERROR(FW21*1,0) -> 0
A22: =IF(C22<>"","DRG-"&TEXT(19,"000"),"") -> DRG-019 | B22: Exception | C22: Exception | D22: Brunche | E22: مقطم | F22: Cairo | L22: 4 | M22: =IF(N22>=4,"✔ Completed","✘ Pending") -> ✘ Pending | N22: =(P22="✔")+(AC22="✔")+(AP22="✔")+(BC22="✔")+(BP22="✔")+(CC22="✔")+(CP22="✔")+(DC22="✔")+(DP22="✔")+(EC22="✔")+(EP22="✔")+(FC22="✔") -> 0 | FO22: =IFERROR(R22*1,0)+IFERROR(AE22*1,0)+IFERROR(AR22*1,0)+IFERROR(BE22*1,0)+IFERROR(BR22*1,0)+IFERROR(CE22*1,0)+IFERROR(CR22*1,0)+IFERROR(DE22*1,0)+IFERROR(DR22*1,0)+IFERROR(EE22*1,0)+IFERROR(ER22*1,0)+IFERROR(FE22*1,0) -> 0 | FP22: =IFERROR(S22*1,0)+IFERROR(AF22*1,0)+IFERROR(AS22*1,0)+IFERROR(BF22*1,0)+IFERROR(BS22*1,0)+IFERROR(CF22*1,0)+IFERROR(CS22*1,0)+IFERROR(DF22*1,0)+IFERROR(DS22*1,0)+IFERROR(EF22*1,0)+IFERROR(ES22*1,0)+IFERROR(FF22*1,0) -> 0 | FQ22: =IFERROR(T22*1,0)+IFERROR(AG22*1,0)+IFERROR(AT22*1,0)+IFERROR(BG22*1,0)+IFERROR(BT22*1,0)+IFERROR(CG22*1,0)+IFERROR(CT22*1,0)+IFERROR(DG22*1,0)+IFERROR(DT22*1,0)+IFERROR(EG22*1,0)+IFERROR(ET22*1,0)+IFERROR(FG22*1,0) -> 0 | FR22: =IFERROR(U22*1,0)+IFERROR(AH22*1,0)+IFERROR(AU22*1,0)+IFERROR(BH22*1,0)+IFERROR(BU22*1,0)+IFERROR(CH22*1,0)+IFERROR(CU22*1,0)+IFERROR(DH22*1,0)+IFERROR(DU22*1,0)+IFERROR(EH22*1,0)+IFERROR(EU22*1,0)+IFERROR(FH22*1,0) -> 0 | FS22: =IFERROR(V22*1,0)+IFERROR(AI22*1,0)+IFERROR(AV22*1,0)+IFERROR(BI22*1,0)+IFERROR(BV22*1,0)+IFERROR(CI22*1,0)+IFERROR(CV22*1,0)+IFERROR(DI22*1,0)+IFERROR(DV22*1,0)+IFERROR(EI22*1,0)+IFERROR(EV22*1,0)+IFERROR(FI22*1,0) -> 0 | FT22: =IFERROR(W22*1,0)+IFERROR(AJ22*1,0)+IFERROR(AW22*1,0)+IFERROR(BJ22*1,0)+IFERROR(BW22*1,0)+IFERROR(CJ22*1,0)+IFERROR(CW22*1,0)+IFERROR(DJ22*1,0)+IFERROR(DW22*1,0)+IFERROR(EJ22*1,0)+IFERROR(EW22*1,0)+IFERROR(FJ22*1,0) -> 0 | FU22: =IFERROR(X22*1,0)+IFERROR(AK22*1,0)+IFERROR(AX22*1,0)+IFERROR(BK22*1,0)+IFERROR(BX22*1,0)+IFERROR(CK22*1,0)+IFERROR(CX22*1,0)+IFERROR(DK22*1,0)+IFERROR(DX22*1,0)+IFERROR(EK22*1,0)+IFERROR(EX22*1,0)+IFERROR(FK22*1,0) -> 0 | FV22: =IFERROR(Y22*1,0)+IFERROR(AL22*1,0)+IFERROR(AY22*1,0)+IFERROR(BL22*1,0)+IFERROR(BY22*1,0)+IFERROR(CL22*1,0)+IFERROR(CY22*1,0)+IFERROR(DL22*1,0)+IFERROR(DY22*1,0)+IFERROR(EL22*1,0)+IFERROR(EY22*1,0)+IFERROR(FL22*1,0) -> 0 | FX22: =N22+IFERROR(FW22*1,0) -> 0
A23: =IF(C23<>"","DRG-"&TEXT(20,"000"),"") -> DRG-020 | B23: Exception | C23: Exception | D23: Brunche | E23: تجمع شارع 90 | F23: Cairo | L23: 4 | M23: =IF(N23>=4,"✔ Completed","✘ Pending") -> ✘ Pending | N23: =(P23="✔")+(AC23="✔")+(AP23="✔")+(BC23="✔")+(BP23="✔")+(CC23="✔")+(CP23="✔")+(DC23="✔")+(DP23="✔")+(EC23="✔")+(EP23="✔")+(FC23="✔") -> 0 | FO23: =IFERROR(R23*1,0)+IFERROR(AE23*1,0)+IFERROR(AR23*1,0)+IFERROR(BE23*1,0)+IFERROR(BR23*1,0)+IFERROR(CE23*1,0)+IFERROR(CR23*1,0)+IFERROR(DE23*1,0)+IFERROR(DR23*1,0)+IFERROR(EE23*1,0)+IFERROR(ER23*1,0)+IFERROR(FE23*1,0) -> 0 | FP23: =IFERROR(S23*1,0)+IFERROR(AF23*1,0)+IFERROR(AS23*1,0)+IFERROR(BF23*1,0)+IFERROR(BS23*1,0)+IFERROR(CF23*1,0)+IFERROR(CS23*1,0)+IFERROR(DF23*1,0)+IFERROR(DS23*1,0)+IFERROR(EF23*1,0)+IFERROR(ES23*1,0)+IFERROR(FF23*1,0) -> 0 | FQ23: =IFERROR(T23*1,0)+IFERROR(AG23*1,0)+IFERROR(AT23*1,0)+IFERROR(BG23*1,0)+IFERROR(BT23*1,0)+IFERROR(CG23*1,0)+IFERROR(CT23*1,0)+IFERROR(DG23*1,0)+IFERROR(DT23*1,0)+IFERROR(EG23*1,0)+IFERROR(ET23*1,0)+IFERROR(FG23*1,0) -> 0 | FR23: =IFERROR(U23*1,0)+IFERROR(AH23*1,0)+IFERROR(AU23*1,0)+IFERROR(BH23*1,0)+IFERROR(BU23*1,0)+IFERROR(CH23*1,0)+IFERROR(CU23*1,0)+IFERROR(DH23*1,0)+IFERROR(DU23*1,0)+IFERROR(EH23*1,0)+IFERROR(EU23*1,0)+IFERROR(FH23*1,0) -> 0 | FS23: =IFERROR(V23*1,0)+IFERROR(AI23*1,0)+IFERROR(AV23*1,0)+IFERROR(BI23*1,0)+IFERROR(BV23*1,0)+IFERROR(CI23*1,0)+IFERROR(CV23*1,0)+IFERROR(DI23*1,0)+IFERROR(DV23*1,0)+IFERROR(EI23*1,0)+IFERROR(EV23*1,0)+IFERROR(FI23*1,0) -> 0 | FT23: =IFERROR(W23*1,0)+IFERROR(AJ23*1,0)+IFERROR(AW23*1,0)+IFERROR(BJ23*1,0)+IFERROR(BW23*1,0)+IFERROR(CJ23*1,0)+IFERROR(CW23*1,0)+IFERROR(DJ23*1,0)+IFERROR(DW23*1,0)+IFERROR(EJ23*1,0)+IFERROR(EW23*1,0)+IFERROR(FJ23*1,0) -> 0 | FU23: =IFERROR(X23*1,0)+IFERROR(AK23*1,0)+IFERROR(AX23*1,0)+IFERROR(BK23*1,0)+IFERROR(BX23*1,0)+IFERROR(CK23*1,0)+IFERROR(CX23*1,0)+IFERROR(DK23*1,0)+IFERROR(DX23*1,0)+IFERROR(EK23*1,0)+IFERROR(EX23*1,0)+IFERROR(FK23*1,0) -> 0 | FV23: =IFERROR(Y23*1,0)+IFERROR(AL23*1,0)+IFERROR(AY23*1,0)+IFERROR(BL23*1,0)+IFERROR(BY23*1,0)+IFERROR(CL23*1,0)+IFERROR(CY23*1,0)+IFERROR(DL23*1,0)+IFERROR(DY23*1,0)+IFERROR(EL23*1,0)+IFERROR(EY23*1,0)+IFERROR(FL23*1,0) -> 0 | FX23: =N23+IFERROR(FW23*1,0) -> 0
A24: =IF(C24<>"","DRG-"&TEXT(21,"000"),"") -> DRG-021 | B24: Exception | C24: Exception | D24: Brunche | E24: رامي هلال | F24: Cairo | L24: 4 | M24: =IF(N24>=4,"✔ Completed","✘ Pending") -> ✘ Pending | N24: =(P24="✔")+(AC24="✔")+(AP24="✔")+(BC24="✔")+(BP24="✔")+(CC24="✔")+(CP24="✔")+(DC24="✔")+(DP24="✔")+(EC24="✔")+(EP24="✔")+(FC24="✔") -> 0 | FO24: =IFERROR(R24*1,0)+IFERROR(AE24*1,0)+IFERROR(AR24*1,0)+IFERROR(BE24*1,0)+IFERROR(BR24*1,0)+IFERROR(CE24*1,0)+IFERROR(CR24*1,0)+IFERROR(DE24*1,0)+IFERROR(DR24*1,0)+IFERROR(EE24*1,0)+IFERROR(ER24*1,0)+IFERROR(FE24*1,0) -> 0 | FP24: =IFERROR(S24*1,0)+IFERROR(AF24*1,0)+IFERROR(AS24*1,0)+IFERROR(BF24*1,0)+IFERROR(BS24*1,0)+IFERROR(CF24*1,0)+IFERROR(CS24*1,0)+IFERROR(DF24*1,0)+IFERROR(DS24*1,0)+IFERROR(EF24*1,0)+IFERROR(ES24*1,0)+IFERROR(FF24*1,0) -> 0 | FQ24: =IFERROR(T24*1,0)+IFERROR(AG24*1,0)+IFERROR(AT24*1,0)+IFERROR(BG24*1,0)+IFERROR(BT24*1,0)+IFERROR(CG24*1,0)+IFERROR(CT24*1,0)+IFERROR(DG24*1,0)+IFERROR(DT24*1,0)+IFERROR(EG24*1,0)+IFERROR(ET24*1,0)+IFERROR(FG24*1,0) -> 0 | FR24: =IFERROR(U24*1,0)+IFERROR(AH24*1,0)+IFERROR(AU24*1,0)+IFERROR(BH24*1,0)+IFERROR(BU24*1,0)+IFERROR(CH24*1,0)+IFERROR(CU24*1,0)+IFERROR(DH24*1,0)+IFERROR(DU24*1,0)+IFERROR(EH24*1,0)+IFERROR(EU24*1,0)+IFERROR(FH24*1,0) -> 0 | FS24: =IFERROR(V24*1,0)+IFERROR(AI24*1,0)+IFERROR(AV24*1,0)+IFERROR(BI24*1,0)+IFERROR(BV24*1,0)+IFERROR(CI24*1,0)+IFERROR(CV24*1,0)+IFERROR(DI24*1,0)+IFERROR(DV24*1,0)+IFERROR(EI24*1,0)+IFERROR(EV24*1,0)+IFERROR(FI24*1,0) -> 0 | FT24: =IFERROR(W24*1,0)+IFERROR(AJ24*1,0)+IFERROR(AW24*1,0)+IFERROR(BJ24*1,0)+IFERROR(BW24*1,0)+IFERROR(CJ24*1,0)+IFERROR(CW24*1,0)+IFERROR(DJ24*1,0)+IFERROR(DW24*1,0)+IFERROR(EJ24*1,0)+IFERROR(EW24*1,0)+IFERROR(FJ24*1,0) -> 0 | FU24: =IFERROR(X24*1,0)+IFERROR(AK24*1,0)+IFERROR(AX24*1,0)+IFERROR(BK24*1,0)+IFERROR(BX24*1,0)+IFERROR(CK24*1,0)+IFERROR(CX24*1,0)+IFERROR(DK24*1,0)+IFERROR(DX24*1,0)+IFERROR(EK24*1,0)+IFERROR(EX24*1,0)+IFERROR(FK24*1,0) -> 0 | FV24: =IFERROR(Y24*1,0)+IFERROR(AL24*1,0)+IFERROR(AY24*1,0)+IFERROR(BL24*1,0)+IFERROR(BY24*1,0)+IFERROR(CL24*1,0)+IFERROR(CY24*1,0)+IFERROR(DL24*1,0)+IFERROR(DY24*1,0)+IFERROR(EL24*1,0)+IFERROR(EY24*1,0)+IFERROR(FL24*1,0) -> 0 | FX24: =N24+IFERROR(FW24*1,0) -> 0
A25: =IF(C25<>"","DRG-"&TEXT(22,"000"),"") -> DRG-022 | B25: Exception | C25: Exception | D25: Brunche | E25: مدينتي | F25: Cairo | L25: 4 | M25: =IF(N25>=4,"✔ Completed","✘ Pending") -> ✘ Pending | N25: =(P25="✔")+(AC25="✔")+(AP25="✔")+(BC25="✔")+(BP25="✔")+(CC25="✔")+(CP25="✔")+(DC25="✔")+(DP25="✔")+(EC25="✔")+(EP25="✔")+(FC25="✔") -> 0 | FO25: =IFERROR(R25*1,0)+IFERROR(AE25*1,0)+IFERROR(AR25*1,0)+IFERROR(BE25*1,0)+IFERROR(BR25*1,0)+IFERROR(CE25*1,0)+IFERROR(CR25*1,0)+IFERROR(DE25*1,0)+IFERROR(DR25*1,0)+IFERROR(EE25*1,0)+IFERROR(ER25*1,0)+IFERROR(FE25*1,0) -> 0 | FP25: =IFERROR(S25*1,0)+IFERROR(AF25*1,0)+IFERROR(AS25*1,0)+IFERROR(BF25*1,0)+IFERROR(BS25*1,0)+IFERROR(CF25*1,0)+IFERROR(CS25*1,0)+IFERROR(DF25*1,0)+IFERROR(DS25*1,0)+IFERROR(EF25*1,0)+IFERROR(ES25*1,0)+IFERROR(FF25*1,0) -> 0 | FQ25: =IFERROR(T25*1,0)+IFERROR(AG25*1,0)+IFERROR(AT25*1,0)+IFERROR(BG25*1,0)+IFERROR(BT25*1,0)+IFERROR(CG25*1,0)+IFERROR(CT25*1,0)+IFERROR(DG25*1,0)+IFERROR(DT25*1,0)+IFERROR(EG25*1,0)+IFERROR(ET25*1,0)+IFERROR(FG25*1,0) -> 0 | FR25: =IFERROR(U25*1,0)+IFERROR(AH25*1,0)+IFERROR(AU25*1,0)+IFERROR(BH25*1,0)+IFERROR(BU25*1,0)+IFERROR(CH25*1,0)+IFERROR(CU25*1,0)+IFERROR(DH25*1,0)+IFERROR(DU25*1,0)+IFERROR(EH25*1,0)+IFERROR(EU25*1,0)+IFERROR(FH25*1,0) -> 0 | FS25: =IFERROR(V25*1,0)+IFERROR(AI25*1,0)+IFERROR(AV25*1,0)+IFERROR(BI25*1,0)+IFERROR(BV25*1,0)+IFERROR(CI25*1,0)+IFERROR(CV25*1,0)+IFERROR(DI25*1,0)+IFERROR(DV25*1,0)+IFERROR(EI25*1,0)+IFERROR(EV25*1,0)+IFERROR(FI25*1,0) -> 0 | FT25: =IFERROR(W25*1,0)+IFERROR(AJ25*1,0)+IFERROR(AW25*1,0)+IFERROR(BJ25*1,0)+IFERROR(BW25*1,0)+IFERROR(CJ25*1,0)+IFERROR(CW25*1,0)+IFERROR(DJ25*1,0)+IFERROR(DW25*1,0)+IFERROR(EJ25*1,0)+IFERROR(EW25*1,0)+IFERROR(FJ25*1,0) -> 0 | FU25: =IFERROR(X25*1,0)+IFERROR(AK25*1,0)+IFERROR(AX25*1,0)+IFERROR(BK25*1,0)+IFERROR(BX25*1,0)+IFERROR(CK25*1,0)+IFERROR(CX25*1,0)+IFERROR(DK25*1,0)+IFERROR(DX25*1,0)+IFERROR(EK25*1,0)+IFERROR(EX25*1,0)+IFERROR(FK25*1,0) -> 0 | FV25: =IFERROR(Y25*1,0)+IFERROR(AL25*1,0)+IFERROR(AY25*1,0)+IFERROR(BL25*1,0)+IFERROR(BY25*1,0)+IFERROR(CL25*1,0)+IFERROR(CY25*1,0)+IFERROR(DL25*1,0)+IFERROR(DY25*1,0)+IFERROR(EL25*1,0)+IFERROR(EY25*1,0)+IFERROR(FL25*1,0) -> 0 | FX25: =N25+IFERROR(FW25*1,0) -> 0
A26: =IF(C26<>"","DRG-"&TEXT(23,"000"),"") -> DRG-023 | B26: Exception | C26: Exception | D26: Brunche | E26: العبور | F26: Qalyubia | L26: 4 | M26: =IF(N26>=4,"✔ Completed","✘ Pending") -> ✘ Pending | N26: =(P26="✔")+(AC26="✔")+(AP26="✔")+(BC26="✔")+(BP26="✔")+(CC26="✔")+(CP26="✔")+(DC26="✔")+(DP26="✔")+(EC26="✔")+(EP26="✔")+(FC26="✔") -> 0 | FO26: =IFERROR(R26*1,0)+IFERROR(AE26*1,0)+IFERROR(AR26*1,0)+IFERROR(BE26*1,0)+IFERROR(BR26*1,0)+IFERROR(CE26*1,0)+IFERROR(CR26*1,0)+IFERROR(DE26*1,0)+IFERROR(DR26*1,0)+IFERROR(EE26*1,0)+IFERROR(ER26*1,0)+IFERROR(FE26*1,0) -> 0 | FP26: =IFERROR(S26*1,0)+IFERROR(AF26*1,0)+IFERROR(AS26*1,0)+IFERROR(BF26*1,0)+IFERROR(BS26*1,0)+IFERROR(CF26*1,0)+IFERROR(CS26*1,0)+IFERROR(DF26*1,0)+IFERROR(DS26*1,0)+IFERROR(EF26*1,0)+IFERROR(ES26*1,0)+IFERROR(FF26*1,0) -> 0 | FQ26: =IFERROR(T26*1,0)+IFERROR(AG26*1,0)+IFERROR(AT26*1,0)+IFERROR(BG26*1,0)+IFERROR(BT26*1,0)+IFERROR(CG26*1,0)+IFERROR(CT26*1,0)+IFERROR(DG26*1,0)+IFERROR(DT26*1,0)+IFERROR(EG26*1,0)+IFERROR(ET26*1,0)+IFERROR(FG26*1,0) -> 0 | FR26: =IFERROR(U26*1,0)+IFERROR(AH26*1,0)+IFERROR(AU26*1,0)+IFERROR(BH26*1,0)+IFERROR(BU26*1,0)+IFERROR(CH26*1,0)+IFERROR(CU26*1,0)+IFERROR(DH26*1,0)+IFERROR(DU26*1,0)+IFERROR(EH26*1,0)+IFERROR(EU26*1,0)+IFERROR(FH26*1,0) -> 0 | FS26: =IFERROR(V26*1,0)+IFERROR(AI26*1,0)+IFERROR(AV26*1,0)+IFERROR(BI26*1,0)+IFERROR(BV26*1,0)+IFERROR(CI26*1,0)+IFERROR(CV26*1,0)+IFERROR(DI26*1,0)+IFERROR(DV26*1,0)+IFERROR(EI26*1,0)+IFERROR(EV26*1,0)+IFERROR(FI26*1,0) -> 0 | FT26: =IFERROR(W26*1,0)+IFERROR(AJ26*1,0)+IFERROR(AW26*1,0)+IFERROR(BJ26*1,0)+IFERROR(BW26*1,0)+IFERROR(CJ26*1,0)+IFERROR(CW26*1,0)+IFERROR(DJ26*1,0)+IFERROR(DW26*1,0)+IFERROR(EJ26*1,0)+IFERROR(EW26*1,0)+IFERROR(FJ26*1,0) -> 0 | FU26: =IFERROR(X26*1,0)+IFERROR(AK26*1,0)+IFERROR(AX26*1,0)+IFERROR(BK26*1,0)+IFERROR(BX26*1,0)+IFERROR(CK26*1,0)+IFERROR(CX26*1,0)+IFERROR(DK26*1,0)+IFERROR(DX26*1,0)+IFERROR(EK26*1,0)+IFERROR(EX26*1,0)+IFERROR(FK26*1,0) -> 0 | FV26: =IFERROR(Y26*1,0)+IFERROR(AL26*1,0)+IFERROR(AY26*1,0)+IFERROR(BL26*1,0)+IFERROR(BY26*1,0)+IFERROR(CL26*1,0)+IFERROR(CY26*1,0)+IFERROR(DL26*1,0)+IFERROR(DY26*1,0)+IFERROR(EL26*1,0)+IFERROR(EY26*1,0)+IFERROR(FL26*1,0) -> 0 | FX26: =N26+IFERROR(FW26*1,0) -> 0
A27: =IF(C27<>"","DRG-"&TEXT(24,"000"),"") -> DRG-024 | B27: Exception | C27: Exception | D27: Brunche | E27: جسر السويس | F27: Cairo | L27: 4 | M27: =IF(N27>=4,"✔ Completed","✘ Pending") -> ✘ Pending | N27: =(P27="✔")+(AC27="✔")+(AP27="✔")+(BC27="✔")+(BP27="✔")+(CC27="✔")+(CP27="✔")+(DC27="✔")+(DP27="✔")+(EC27="✔")+(EP27="✔")+(FC27="✔") -> 0 | FO27: =IFERROR(R27*1,0)+IFERROR(AE27*1,0)+IFERROR(AR27*1,0)+IFERROR(BE27*1,0)+IFERROR(BR27*1,0)+IFERROR(CE27*1,0)+IFERROR(CR27*1,0)+IFERROR(DE27*1,0)+IFERROR(DR27*1,0)+IFERROR(EE27*1,0)+IFERROR(ER27*1,0)+IFERROR(FE27*1,0) -> 0 | FP27: =IFERROR(S27*1,0)+IFERROR(AF27*1,0)+IFERROR(AS27*1,0)+IFERROR(BF27*1,0)+IFERROR(BS27*1,0)+IFERROR(CF27*1,0)+IFERROR(CS27*1,0)+IFERROR(DF27*1,0)+IFERROR(DS27*1,0)+IFERROR(EF27*1,0)+IFERROR(ES27*1,0)+IFERROR(FF27*1,0) -> 0 | FQ27: =IFERROR(T27*1,0)+IFERROR(AG27*1,0)+IFERROR(AT27*1,0)+IFERROR(BG27*1,0)+IFERROR(BT27*1,0)+IFERROR(CG27*1,0)+IFERROR(CT27*1,0)+IFERROR(DG27*1,0)+IFERROR(DT27*1,0)+IFERROR(EG27*1,0)+IFERROR(ET27*1,0)+IFERROR(FG27*1,0) -> 0 | FR27: =IFERROR(U27*1,0)+IFERROR(AH27*1,0)+IFERROR(AU27*1,0)+IFERROR(BH27*1,0)+IFERROR(BU27*1,0)+IFERROR(CH27*1,0)+IFERROR(CU27*1,0)+IFERROR(DH27*1,0)+IFERROR(DU27*1,0)+IFERROR(EH27*1,0)+IFERROR(EU27*1,0)+IFERROR(FH27*1,0) -> 0 | FS27: =IFERROR(V27*1,0)+IFERROR(AI27*1,0)+IFERROR(AV27*1,0)+IFERROR(BI27*1,0)+IFERROR(BV27*1,0)+IFERROR(CI27*1,0)+IFERROR(CV27*1,0)+IFERROR(DI27*1,0)+IFERROR(DV27*1,0)+IFERROR(EI27*1,0)+IFERROR(EV27*1,0)+IFERROR(FI27*1,0) -> 0 | FT27: =IFERROR(W27*1,0)+IFERROR(AJ27*1,0)+IFERROR(AW27*1,0)+IFERROR(BJ27*1,0)+IFERROR(BW27*1,0)+IFERROR(CJ27*1,0)+IFERROR(CW27*1,0)+IFERROR(DJ27*1,0)+IFERROR(DW27*1,0)+IFERROR(EJ27*1,0)+IFERROR(EW27*1,0)+IFERROR(FJ27*1,0) -> 0 | FU27: =IFERROR(X27*1,0)+IFERROR(AK27*1,0)+IFERROR(AX27*1,0)+IFERROR(BK27*1,0)+IFERROR(BX27*1,0)+IFERROR(CK27*1,0)+IFERROR(CX27*1,0)+IFERROR(DK27*1,0)+IFERROR(DX27*1,0)+IFERROR(EK27*1,0)+IFERROR(EX27*1,0)+IFERROR(FK27*1,0) -> 0 | FV27: =IFERROR(Y27*1,0)+IFERROR(AL27*1,0)+IFERROR(AY27*1,0)+IFERROR(BL27*1,0)+IFERROR(BY27*1,0)+IFERROR(CL27*1,0)+IFERROR(CY27*1,0)+IFERROR(DL27*1,0)+IFERROR(DY27*1,0)+IFERROR(EL27*1,0)+IFERROR(EY27*1,0)+IFERROR(FL27*1,0) -> 0 | FX27: =N27+IFERROR(FW27*1,0) -> 0
A28: =IF(C28<>"","DRG-"&TEXT(25,"000"),"") -> DRG-025 | B28: Exception | C28: Exception | D28: Brunche | E28: مدينه نصر | F28: Cairo | L28: 4 | M28: =IF(N28>=4,"✔ Completed","✘ Pending") -> ✘ Pending | N28: =(P28="✔")+(AC28="✔")+(AP28="✔")+(BC28="✔")+(BP28="✔")+(CC28="✔")+(CP28="✔")+(DC28="✔")+(DP28="✔")+(EC28="✔")+(EP28="✔")+(FC28="✔") -> 0 | FO28: =IFERROR(R28*1,0)+IFERROR(AE28*1,0)+IFERROR(AR28*1,0)+IFERROR(BE28*1,0)+IFERROR(BR28*1,0)+IFERROR(CE28*1,0)+IFERROR(CR28*1,0)+IFERROR(DE28*1,0)+IFERROR(DR28*1,0)+IFERROR(EE28*1,0)+IFERROR(ER28*1,0)+IFERROR(FE28*1,0) -> 0 | FP28: =IFERROR(S28*1,0)+IFERROR(AF28*1,0)+IFERROR(AS28*1,0)+IFERROR(BF28*1,0)+IFERROR(BS28*1,0)+IFERROR(CF28*1,0)+IFERROR(CS28*1,0)+IFERROR(DF28*1,0)+IFERROR(DS28*1,0)+IFERROR(EF28*1,0)+IFERROR(ES28*1,0)+IFERROR(FF28*1,0) -> 0 | FQ28: =IFERROR(T28*1,0)+IFERROR(AG28*1,0)+IFERROR(AT28*1,0)+IFERROR(BG28*1,0)+IFERROR(BT28*1,0)+IFERROR(CG28*1,0)+IFERROR(CT28*1,0)+IFERROR(DG28*1,0)+IFERROR(DT28*1,0)+IFERROR(EG28*1,0)+IFERROR(ET28*1,0)+IFERROR(FG28*1,0) -> 0 | FR28: =IFERROR(U28*1,0)+IFERROR(AH28*1,0)+IFERROR(AU28*1,0)+IFERROR(BH28*1,0)+IFERROR(BU28*1,0)+IFERROR(CH28*1,0)+IFERROR(CU28*1,0)+IFERROR(DH28*1,0)+IFERROR(DU28*1,0)+IFERROR(EH28*1,0)+IFERROR(EU28*1,0)+IFERROR(FH28*1,0) -> 0 | FS28: =IFERROR(V28*1,0)+IFERROR(AI28*1,0)+IFERROR(AV28*1,0)+IFERROR(BI28*1,0)+IFERROR(BV28*1,0)+IFERROR(CI28*1,0)+IFERROR(CV28*1,0)+IFERROR(DI28*1,0)+IFERROR(DV28*1,0)+IFERROR(EI28*1,0)+IFERROR(EV28*1,0)+IFERROR(FI28*1,0) -> 0 | FT28: =IFERROR(W28*1,0)+IFERROR(AJ28*1,0)+IFERROR(AW28*1,0)+IFERROR(BJ28*1,0)+IFERROR(BW28*1,0)+IFERROR(CJ28*1,0)+IFERROR(CW28*1,0)+IFERROR(DJ28*1,0)+IFERROR(DW28*1,0)+IFERROR(EJ28*1,0)+IFERROR(EW28*1,0)+IFERROR(FJ28*1,0) -> 0 | FU28: =IFERROR(X28*1,0)+IFERROR(AK28*1,0)+IFERROR(AX28*1,0)+IFERROR(BK28*1,0)+IFERROR(BX28*1,0)+IFERROR(CK28*1,0)+IFERROR(CX28*1,0)+IFERROR(DK28*1,0)+IFERROR(DX28*1,0)+IFERROR(EK28*1,0)+IFERROR(EX28*1,0)+IFERROR(FK28*1,0) -> 0 | FV28: =IFERROR(Y28*1,0)+IFERROR(AL28*1,0)+IFERROR(AY28*1,0)+IFERROR(BL28*1,0)+IFERROR(BY28*1,0)+IFERROR(CL28*1,0)+IFERROR(CY28*1,0)+IFERROR(DL28*1,0)+IFERROR(DY28*1,0)+IFERROR(EL28*1,0)+IFERROR(EY28*1,0)+IFERROR(FL28*1,0) -> 0 | FX28: =N28+IFERROR(FW28*1,0) -> 0
